Workbook

Sheet 店长看板
A1: 店长看板 · Store Manager Daily Dashboard
A2: 先看灯，再看今天的三件事，最后才翻矩阵找原因。所有数值来自「每日经营日报」，所有红黄绿来自「目标与口径」——两张表都改得动。
A3: 最新营业日 | B3: =MAX(每日经营日报!$A$5:$A$18) -> 46252 | D3: 当日结论 | E3: =IF(COUNTIF($D$6:$D$22,"红")>0,"有 "&COUNTIF($D$6:$D$22,"红")&" 项红灯，按下方「今天的三件事」执行",IF(COUNTIF($D$6:$D$22,"黄")>0,"无红灯，"&COUNTIF($D$6:$D$22,"黄")&" 项关注","全绿：把时间用在训练和顾客身上")) -> 有 3 项红灯，按下方「今天的三件事」执行
A5: 指标 | B5: 最新值 | C5: 目标 | D5: 状态 | E5: 绿线 | F5: 黄线 | G5: 超线带宽 | H5: 责任人 | I5: 行动卡
A6: 销售达成率 | B6: =IFERROR(INDEX(每日经营日报!$G$5:$G$18,MATCH($B$3,每日经营日报!$A$5:$A$18,0)),0) -> 0.97868414 | C6: =INDEX(目标与口径!$F$5:$F$36,MATCH("sales_vs_forecast",目标与口径!$A$5:$A$36,0)) -> 1 | D6: =IFERROR(IF(INDEX(目标与口径!$E$5:$E$36,MATCH("sales_vs_forecast",目标与口径!$A$5:$A$36,0))="越高越好",IF($B$6>=INDEX(目标与口径!$G$5:$G$36,MATCH("sales_vs_forecast",目标与口径!$A$5:$A$36,0)),"绿",IF($B$6>=INDEX(目标与口径!$H$5:$H$36,MATCH("sales_vs_forecast",目标与口径!$A$5:$A$36,0)),"黄","红")),IF($B$6<=INDEX(目标与口径!$G$5:$G$36,MATCH("sales_vs_forecast",目标与口径!$A$5:$A$36,0)),"绿",IF($B$6<=INDEX(目标与口径!$H$5:$H$36,MATCH("sales_vs_forecast",目标与口径!$A$5:$A$36,0)),"黄","红"))),"—") -> 黄 | E6: =INDEX(目标与口径!$G$5:$G$36,MATCH("sales_vs_forecast",目标与口径!$A$5:$A$36,0)) -> 0.98 | F6: =INDEX(目标与口径!$H$5:$H$36,MATCH("sales_vs_forecast",目标与口径!$A$5:$A$36,0)) -> 0.93 | G6: =IFERROR(MAX(0,IF(INDEX(目标与口径!$E$5:$E$36,MATCH("sales_vs_forecast",目标与口径!$A$5:$A$36,0))="越高越好",INDEX(目标与口径!$G$5:$G$36,MATCH("sales_vs_forecast",目标与口径!$A$5:$A$36,0))-$B$6,$B$6-INDEX(目标与口径!$G$5:$G$36,MATCH("sales_vs_forecast",目标与口径!$A$5:$A$36,0)))/ABS(INDEX(目标与口径!$H$5:$H$36,MATCH("sales_vs_forecast",目标与口径!$A$5:$A$36,0))-INDEX(目标与口径!$G$5:$G$36,MATCH("sales_vs_forecast",目标与口径!$A$5:$A$36,0)))),0) -> 0.026317265 | H6: =INDEX(目标与口径!$J$5:$J$36,MATCH("sales_vs_forecast",目标与口径!$A$5:$A$36,0)) -> 店长 | I6: =INDEX(目标与口径!$N$5:$N$36,MATCH("sales_vs_forecast",目标与口径!$A$5:$A$36,0)) -> PB-01
A7: 净销售额 | B7: =IFERROR(INDEX(每日经营日报!$D$5:$D$18,MATCH($B$3,每日经营日报!$A$5:$A$18,0)),0) -> 55987.74 | C7: =INDEX(目标与口径!$F$5:$F$36,MATCH("net_sales",目标与口径!$A$5:$A$36,0)) -> 62000 | D7: =IFERROR(IF(INDEX(目标与口径!$E$5:$E$36,MATCH("net_sales",目标与口径!$A$5:$A$36,0))="越高越好",IF($B$7>=INDEX(目标与口径!$G$5:$G$36,MATCH("net_sales",目标与口径!$A$5:$A$36,0)),"绿",IF($B$7>=INDEX(目标与口径!$H$5:$H$36,MATCH("net_sales",目标与口径!$A$5:$A$36,0)),"黄","红")),IF($B$7<=INDEX(目标与口径!$G$5:$G$36,MATCH("net_sales",目标与口径!$A$5:$A$36,0)),"绿",IF($B$7<=INDEX(目标与口径!$H$5:$H$36,MATCH("net_sales",目标与口径!$A$5:$A$36,0)),"黄","红"))),"—") -> 黄 | E7: =INDEX(目标与口径!$G$5:$G$36,MATCH("net_sales",目标与口径!$A$5:$A$36,0)) -> 58000 | F7: =INDEX(目标与口径!$H$5:$H$36,MATCH("net_sales",目标与口径!$A$5:$A$36,0)) -> 52000 | G7: =IFERROR(MAX(0,IF(INDEX(目标与口径!$E$5:$E$36,MATCH("net_sales",目标与口径!$A$5:$A$36,0))="越高越好",INDEX(目标与口径!$G$5:$G$36,MATCH("net_sales",目标与口径!$A$5:$A$36,0))-$B$7,$B$7-INDEX(目标与口径!$G$5:$G$36,MATCH("net_sales",目标与口径!$A$5:$A$36,0)))/ABS(INDEX(目标与口径!$H$5:$H$36,MATCH("net_sales",目标与口径!$A$5:$A$36,0))-INDEX(目标与口径!$G$5:$G$36,MATCH("net_sales",目标与口径!$A$5:$A$36,0)))),0) -> 0.33537667 | H7: =INDEX(目标与口径!$J$5:$J$36,MATCH("net_sales",目标与口径!$A$5:$A$36,0)) -> 店长 | I7: =INDEX(目标与口径!$N$5:$N$36,MATCH("net_sales",目标与口径!$A$5:$A$36,0)) -> PB-01
A8: 交易笔数 | B8: =IFERROR(INDEX(每日经营日报!$E$5:$E$18,MATCH($B$3,每日经营日报!$A$5:$A$18,0)),0) -> 1564 | C8: =INDEX(目标与口径!$F$5:$F$36,MATCH("guest_count",目标与口径!$A$5:$A$36,0)) -> 1750 | D8: =IFERROR(IF(INDEX(目标与口径!$E$5:$E$36,MATCH("guest_count",目标与口径!$A$5:$A$36,0))="越高越好",IF($B$8>=INDEX(目标与口径!$G$5:$G$36,MATCH("guest_count",目标与口径!$A$5:$A$36,0)),"绿",IF($B$8>=INDEX(目标与口径!$H$5:$H$36,MATCH("guest_count",目标与口径!$A$5:$A$36,0)),"黄","红")),IF($B$8<=INDEX(目标与口径!$G$5:$G$36,MATCH("guest_count",目标与口径!$A$5:$A$36,0)),"绿",IF($B$8<=INDEX(目标与口径!$H$5:$H$36,MATCH("guest_count",目标与口径!$A$5:$A$36,0)),"黄","红"))),"—") -> 黄 | E8: =INDEX(目标与口径!$G$5:$G$36,MATCH("guest_count",目标与口径!$A$5:$A$36,0)) -> 1620 | F8: =INDEX(目标与口径!$H$5:$H$36,MATCH("guest_count",目标与口径!$A$5:$A$36,0)) -> 1480 | G8: =IFERROR(MAX(0,IF(INDEX(目标与口径!$E$5:$E$36,MATCH("guest_count",目标与口径!$A$5:$A$36,0))="越高越好",INDEX(目标与口径!$G$5:$G$36,MATCH("guest_count",目标与口径!$A$5:$A$36,0))-$B$8,$B$8-INDEX(目标与口径!$G$5:$G$36,MATCH("guest_count",目标与口径!$A$5:$A$36,0)))/ABS(INDEX(目标与口径!$H$5:$H$36,MATCH("guest_count",目标与口径!$A$5:$A$36,0))-INDEX(目标与口径!$G$5:$G$36,MATCH("guest_count",目标与口径!$A$5:$A$36,0)))),0) -> 0.4 | H8: =INDEX(目标与口径!$J$5:$J$36,MATCH("guest_count",目标与口径!$A$5:$A$36,0)) -> 店长 | I8: =INDEX(目标与口径!$N$5:$N$36,MATCH("guest_count",目标与口径!$A$5:$A$36,0)) -> PB-01
A9: 客单价 | B9: =IFERROR(INDEX(每日经营日报!$F$5:$F$18,MATCH($B$3,每日经营日报!$A$5:$A$18,0)),0) -> 35.797788 | C9: =INDEX(目标与口径!$F$5:$F$36,MATCH("avg_check",目标与口径!$A$5:$A$36,0)) -> 35.5 | D9: =IFERROR(IF(INDEX(目标与口径!$E$5:$E$36,MATCH("avg_check",目标与口径!$A$5:$A$36,0))="越高越好",IF($B$9>=INDEX(目标与口径!$G$5:$G$36,MATCH("avg_check",目标与口径!$A$5:$A$36,0)),"绿",IF($B$9>=INDEX(目标与口径!$H$5:$H$36,MATCH("avg_check",目标与口径!$A$5:$A$36,0)),"黄","红")),IF($B$9<=INDEX(目标与口径!$G$5:$G$36,MATCH("avg_check",目标与口径!$A$5:$A$36,0)),"绿",IF($B$9<=INDEX(目标与口径!$H$5:$H$36,MATCH("avg_check",目标与口径!$A$5:$A$36,0)),"黄","红"))),"—") -> 绿 | E9: =INDEX(目标与口径!$G$5:$G$36,MATCH("avg_check",目标与口径!$A$5:$A$36,0)) -> 35 | F9: =INDEX(目标与口径!$H$5:$H$36,MATCH("avg_check",目标与口径!$A$5:$A$36,0)) -> 33 | G9: =IFERROR(MAX(0,IF(INDEX(目标与口径!$E$5:$E$36,MATCH("avg_check",目标与口径!$A$5:$A$36,0))="越高越好",INDEX(目标与口径!$G$5:$G$36,MATCH("avg_check",目标与口径!$A$5:$A$36,0))-$B$9,$B$9-INDEX(目标与口径!$G$5:$G$36,MATCH("avg_check",目标与口径!$A$5:$A$36,0)))/ABS(INDEX(目标与口径!$H$5:$H$36,MATCH("avg_check",目标与口径!$A$5:$A$36,0))-INDEX(目标与口径!$G$5:$G$36,MATCH("avg_check",目标与口径!$A$5:$A$36,0)))),0) -> 0 | H9: =INDEX(目标与口径!$J$5:$J$36,MATCH("avg_check",目标与口径!$A$5:$A$36,0)) -> 值班经理 | I9: =INDEX(目标与口径!$N$5:$N$36,MATCH("avg_check",目标与口径!$A$5:$A$36,0)) -> PB-02
A10: 食品成本率 | B10: =IFERROR(INDEX(每日经营日报!$Q$5:$Q$18,MATCH($B$3,每日经营日报!$A$5:$A$18,0)),0) -> 0.31219353 | C10: =INDEX(目标与口径!$F$5:$F$36,MATCH("food_cost_pct",目标与口径!$A$5:$A$36,0)) -> 0.305 | D10: =IFERROR(IF(INDEX(目标与口径!$E$5:$E$36,MATCH("food_cost_pct",目标与口径!$A$5:$A$36,0))="越高越好",IF($B$10>=INDEX(目标与口径!$G$5:$G$36,MATCH("food_cost_pct",目标与口径!$A$5:$A$36,0)),"绿",IF($B$10>=INDEX(目标与口径!$H$5:$H$36,MATCH("food_cost_pct",目标与口径!$A$5:$A$36,0)),"黄","红")),IF($B$10<=INDEX(目标与口径!$G$5:$G$36,MATCH("food_cost_pct",目标与口径!$A$5:$A$36,0)),"绿",IF($B$10<=INDEX(目标与口径!$H$5:$H$36,MATCH("food_cost_pct",目标与口径!$A$5:$A$36,0)),"黄","红"))),"—") -> 黄 | E10: =INDEX(目标与口径!$G$5:$G$36,MATCH("food_cost_pct",目标与口径!$A$5:$A$36,0)) -> 0.31 | F10: =INDEX(目标与口径!$H$5:$H$36,MATCH("food_cost_pct",目标与口径!$A$5:$A$36,0)) -> 0.325 | G10: =IFERROR(MAX(0,IF(INDEX(目标与口径!$E$5:$E$36,MATCH("food_cost_pct",目标与口径!$A$5:$A$36,0))="越高越好",INDEX(目标与口径!$G$5:$G$36,MATCH("food_cost_pct",目标与口径!$A$5:$A$36,0))-$B$10,$B$10-INDEX(目标与口径!$G$5:$G$36,MATCH("food_cost_pct",目标与口径!$A$5:$A$36,0)))/ABS(INDEX(目标与口径!$H$5:$H$36,MATCH("food_cost_pct",目标与口径!$A$5:$A$36,0))-INDEX(目标与口径!$G$5:$G$36,MATCH("food_cost_pct",目标与口径!$A$5:$A$36,0)))),0) -> 0.14623511 | H10: =INDEX(目标与口径!$J$5:$J$36,MATCH("food_cost_pct",目标与口径!$A$5:$A$36,0)) -> 店长 | I10: =INDEX(目标与口径!$N$5:$N$36,MATCH("food_cost_pct",目标与口径!$A$5:$A$36,0)) -> PB-06
A11: 废弃率 | B11: =IFERROR(INDEX(每日经营日报!$S$5:$S$18,MATCH($B$3,每日经营日报!$A$5:$A$18,0)),0) -> 0.011011518 | C11: =INDEX(目标与口径!$F$5:$F$36,MATCH("waste_pct",目标与口径!$A$5:$A$36,0)) -> 0.008 | D11: =IFERROR(IF(INDEX(目标与口径!$E$5:$E$36,MATCH("waste_pct",目标与口径!$A$5:$A$36,0))="越高越好",IF($B$11>=INDEX(目标与口径!$G$5:$G$36,MATCH("waste_pct",目标与口径!$A$5:$A$36,0)),"绿",IF($B$11>=INDEX(目标与口径!$H$5:$H$36,MATCH("waste_pct",目标与口径!$A$5:$A$36,0)),"黄","红")),IF($B$11<=INDEX(目标与口径!$G$5:$G$36,MATCH("waste_pct",目标与口径!$A$5:$A$36,0)),"绿",IF($B$11<=INDEX(目标与口径!$H$5:$H$36,MATCH("waste_pct",目标与口径!$A$5:$A$36,0)),"黄","红"))),"—") -> 黄 | E11: =INDEX(目标与口径!$G$5:$G$36,MATCH("waste_pct",目标与口径!$A$5:$A$36,0)) -> 0.01 | F11: =INDEX(目标与口径!$H$5:$H$36,MATCH("waste_pct",目标与口径!$A$5:$A$36,0)) -> 0.015 | G11: =IFERROR(MAX(0,IF(INDEX(目标与口径!$E$5:$E$36,MATCH("waste_pct",目标与口径!$A$5:$A$36,0))="越高越好",INDEX(目标与口径!$G$5:$G$36,MATCH("waste_pct",目标与口径!$A$5:$A$36,0))-$B$11,$B$11-INDEX(目标与口径!$G$5:$G$36,MATCH("waste_pct",目标与口径!$A$5:$A$36,0)))/ABS(INDEX(目标与口径!$H$5:$H$36,MATCH("waste_pct",目标与口径!$A$5:$A$36,0))-INDEX(目标与口径!$G$5:$G$36,MATCH("waste_pct",目标与口径!$A$5:$A$36,0)))),0) -> 0.20230358 | H11: =INDEX(目标与口径!$J$5:$J$36,MATCH("waste_pct",目标与口径!$A$5:$A$36,0)) -> 值班经理 | I11: =INDEX(目标与口径!$N$5:$N$36,MATCH("waste_pct",目标与口径!$A$5:$A$36,0)) -> PB-06
A12: 人工成本率 | B12: =IFERROR(INDEX(每日经营日报!$Z$5:$Z$18,MATCH($B$3,每日经营日报!$A$5:$A$18,0)),0) -> 0.13246748 | C12: =INDEX(目标与口径!$F$5:$F$36,MATCH("labor_cost_pct",目标与口径!$A$5:$A$36,0)) -> 0.135 | D12: =IFERROR(IF(INDEX(目标与口径!$E$5:$E$36,MATCH("labor_cost_pct",目标与口径!$A$5:$A$36,0))="越高越好",IF($B$12>=INDEX(目标与口径!$G$5:$G$36,MATCH("labor_cost_pct",目标与口径!$A$5:$A$36,0)),"绿",IF($B$12>=INDEX(目标与口径!$H$5:$H$36,MATCH("labor_cost_pct",目标与口径!$A$5:$A$36,0)),"黄","红")),IF($B$12<=INDEX(目标与口径!$G$5:$G$36,MATCH("labor_cost_pct",目标与口径!$A$5:$A$36,0)),"绿",IF($B$12<=INDEX(目标与口径!$H$5:$H$36,MATCH("labor_cost_pct",目标与口径!$A$5:$A$36,0)),"黄","红"))),"—") -> 绿 | E12: =INDEX(目标与口径!$G$5:$G$36,MATCH("labor_cost_pct",目标与口径!$A$5:$A$36,0)) -> 0.14 | F12: =INDEX(目标与口径!$H$5:$H$36,MATCH("labor_cost_pct",目标与口径!$A$5:$A$36,0)) -> 0.155 | G12: =IFERROR(MAX(0,IF(INDEX(目标与口径!$E$5:$E$36,MATCH("labor_cost_pct",目标与口径!$A$5:$A$36,0))="越高越好",INDEX(目标与口径!$G$5:$G$36,MATCH("labor_cost_pct",目标与口径!$A$5:$A$36,0))-$B$12,$B$12-INDEX(目标与口径!$G$5:$G$36,MATCH("labor_cost_pct",目标与口径!$A$5:$A$36,0)))/ABS(INDEX(目标与口径!$H$5:$H$36,MATCH("labor_cost_pct",目标与口径!$A$5:$A$36,0))-INDEX(目标与口径!$G$5:$G$36,MATCH("labor_cost_pct",目标与口径!$A$5:$A$36,0)))),0) -> 0 | H12: =INDEX(目标与口径!$J$5:$J$36,MATCH("labor_cost_pct",目标与口径!$A$5:$A$36,0)) -> 店长 | I12: =INDEX(目标与口径!$N$5:$N$36,MATCH("labor_cost_pct",目标与口径!$A$5:$A$36,0)) -> PB-07
A13: 人时销售 SPLH | B13: =IFERROR(INDEX(每日经营日报!$AA$5:$AA$18,MATCH($B$3,每日经营日报!$A$5:$A$18,0)),0) -> 215.14714 | C13: =INDEX(目标与口径!$F$5:$F$36,MATCH("splh",目标与口径!$A$5:$A$36,0)) -> 210 | D13: =IFERROR(IF(INDEX(目标与口径!$E$5:$E$36,MATCH("splh",目标与口径!$A$5:$A$36,0))="越高越好",IF($B$13>=INDEX(目标与口径!$G$5:$G$36,MATCH("splh",目标与口径!$A$5:$A$36,0)),"绿",IF($B$13>=INDEX(目标与口径!$H$5:$H$36,MATCH("splh",目标与口径!$A$5:$A$36,0)),"黄","红")),IF($B$13<=INDEX(目标与口径!$G$5:$G$36,MATCH("splh",目标与口径!$A$5:$A$36,0)),"绿",IF($B$13<=INDEX(目标与口径!$H$5:$H$36,MATCH("splh",目标与口径!$A$5:$A$36,0)),"黄","红"))),"—") -> 绿 | E13: =INDEX(目标与口径!$G$5:$G$36,MATCH("splh",目标与口径!$A$5:$A$36,0)) -> 205 | F13: =INDEX(目标与口径!$H$5:$H$36,MATCH("splh",目标与口径!$A$5:$A$36,0)) -> 185 | G13: =IFERROR(MAX(0,IF(INDEX(目标与口径!$E$5:$E$36,MATCH("splh",目标与口径!$A$5:$A$36,0))="越高越好",INDEX(目标与口径!$G$5:$G$36,MATCH("splh",目标与口径!$A$5:$A$36,0))-$B$13,$B$13-INDEX(目标与口径!$G$5:$G$36,MATCH("splh",目标与口径!$A$5:$A$36,0)))/ABS(INDEX(目标与口径!$H$5:$H$36,MATCH("splh",目标与口径!$A$5:$A$36,0))-INDEX(目标与口径!$G$5:$G$36,MATCH("splh",目标与口径!$A$5:$A$36,0)))),0) -> 0 | H13: =INDEX(目标与口径!$J$5:$J$36,MATCH("splh",目标与口径!$A$5:$A$36,0)) -> 值班经理 | I13: =INDEX(目标与口径!$N$5:$N$36,MATCH("splh",目标与口径!$A$5:$A$36,0)) -> PB-07
A14: 服务速度达标率 | B14: =IFERROR(INDEX(每日经营日报!$AI$5:$AI$18,MATCH($B$3,每日经营日报!$A$5:$A$18,0)),0) -> 0.76598465 | C14: =INDEX(目标与口径!$F$5:$F$36,MATCH("speed_hit_rate",目标与口径!$A$5:$A$36,0)) -> 0.9 | D14: =IFERROR(IF(INDEX(目标与口径!$E$5:$E$36,MATCH("speed_hit_rate",目标与口径!$A$5:$A$36,0))="越高越好",IF($B$14>=INDEX(目标与口径!$G$5:$G$36,MATCH("speed_hit_rate",目标与口径!$A$5:$A$36,0)),"绿",IF($B$14>=INDEX(目标与口径!$H$5:$H$36,MATCH("speed_hit_rate",目标与口径!$A$5:$A$36,0)),"黄","红")),IF($B$14<=INDEX(目标与口径!$G$5:$G$36,MATCH("speed_hit_rate",目标与口径!$A$5:$A$36,0)),"绿",IF($B$14<=INDEX(目标与口径!$H$5:$H$36,MATCH("speed_hit_rate",目标与口径!$A$5:$A$36,0)),"黄","红"))),"—") -> 红 | E14: =INDEX(目标与口径!$G$5:$G$36,MATCH("speed_hit_rate",目标与口径!$A$5:$A$36,0)) -> 0.88 | F14: =INDEX(目标与口径!$H$5:$H$36,MATCH("speed_hit_rate",目标与口径!$A$5:$A$36,0)) -> 0.8 | G14: =IFERROR(MAX(0,IF(INDEX(目标与口径!$E$5:$E$36,MATCH("speed_hit_rate",目标与口径!$A$5:$A$36,0))="越高越好",INDEX(目标与口径!$G$5:$G$36,MATCH("speed_hit_rate",目标与口径!$A$5:$A$36,0))-$B$14,$B$14-INDEX(目标与口径!$G$5:$G$36,MATCH("speed_hit_rate",目标与口径!$A$5:$A$36,0)))/ABS(INDEX(目标与口径!$H$5:$H$36,MATCH("speed_hit_rate",目标与口径!$A$5:$A$36,0))-INDEX(目标与口径!$G$5:$G$36,MATCH("speed_hit_rate",目标与口径!$A$5:$A$36,0)))),0) -> 1.4251918 | H14: =INDEX(目标与口径!$J$5:$J$36,MATCH("speed_hit_rate",目标与口径!$A$5:$A$36,0)) -> 值班经理 | I14: =INDEX(目标与口径!$N$5:$N$36,MATCH("speed_hit_rate",目标与口径!$A$5:$A$36,0)) -> PB-04
A15: 得来速总时长 | B15: =IFERROR(INDEX(每日经营日报!$AC$5:$AC$18,MATCH($B$3,每日经营日报!$A$5:$A$18,0)),0) -> 158.34 | C15: =INDEX(目标与口径!$F$5:$F$36,MATCH("dt_total_time",目标与口径!$A$5:$A$36,0)) -> 180 | D15: =IFERROR(IF(INDEX(目标与口径!$E$5:$E$36,MATCH("dt_total_time",目标与口径!$A$5:$A$36,0))="越高越好",IF($B$15>=INDEX(目标与口径!$G$5:$G$36,MATCH("dt_total_time",目标与口径!$A$5:$A$36,0)),"绿",IF($B$15>=INDEX(目标与口径!$H$5:$H$36,MATCH("dt_total_time",目标与口径!$A$5:$A$36,0)),"黄","红")),IF($B$15<=INDEX(目标与口径!$G$5:$G$36,MATCH("dt_total_time",目标与口径!$A$5:$A$36,0)),"绿",IF($B$15<=INDEX(目标与口径!$H$5:$H$36,MATCH("dt_total_time",目标与口径!$A$5:$A$36,0)),"黄","红"))),"—") -> 绿 | E15: =INDEX(目标与口径!$G$5:$G$36,MATCH("dt_total_time",目标与口径!$A$5:$A$36,0)) -> 190 | F15: =INDEX(目标与口径!$H$5:$H$36,MATCH("dt_total_time",目标与口径!$A$5:$A$36,0)) -> 215 | G15: =IFERROR(MAX(0,IF(INDEX(目标与口径!$E$5:$E$36,MATCH("dt_total_time",目标与口径!$A$5:$A$36,0))="越高越好",INDEX(目标与口径!$G$5:$G$36,MATCH("dt_total_time",目标与口径!$A$5:$A$36,0))-$B$15,$B$15-INDEX(目标与口径!$G$5:$G$36,MATCH("dt_total_time",目标与口径!$A$5:$A$36,0)))/ABS(INDEX(目标与口径!$H$5:$H$36,MATCH("dt_total_time",目标与口径!$A$5:$A$36,0))-INDEX(目标与口径!$G$5:$G$36,MATCH("dt_total_time",目标与口径!$A$5:$A$36,0)))),0) -> 0 | H15: =INDEX(目标与口径!$J$5:$J$36,MATCH("dt_total_time",目标与口径!$A$5:$A$36,0)) -> 值班经理 | I15: =INDEX(目标与口径!$N$5:$N$36,MATCH("dt_total_time",目标与口径!$A$5:$A$36,0)) -> PB-04
A16: 订单准确率 | B16: =IFERROR(INDEX(每日经营日报!$AK$5:$AK$18,MATCH($B$3,每日经营日报!$A$5:$A$18,0)),0) -> 0.99936061 | C16: =INDEX(目标与口径!$F$5:$F$36,MATCH("order_accuracy",目标与口径!$A$5:$A$36,0)) -> 0.996 | D16: =IFERROR(IF(INDEX(目标与口径!$E$5:$E$36,MATCH("order_accuracy",目标与口径!$A$5:$A$36,0))="越高越好",IF($B$16>=INDEX(目标与口径!$G$5:$G$36,MATCH("order_accuracy",目标与口径!$A$5:$A$36,0)),"绿",IF($B$16>=INDEX(目标与口径!$H$5:$H$36,MATCH("order_accuracy",目标与口径!$A$5:$A$36,0)),"黄","红")),IF($B$16<=INDEX(目标与口径!$G$5:$G$36,MATCH("order_accuracy",目标与口径!$A$5:$A$36,0)),"绿",IF($B$16<=INDEX(目标与口径!$H$5:$H$36,MATCH("order_accuracy",目标与口径!$A$5:$A$36,0)),"黄","红"))),"—") -> 绿 | E16: =INDEX(目标与口径!$G$5:$G$36,MATCH("order_accuracy",目标与口径!$A$5:$A$36,0)) -> 0.994 | F16: =INDEX(目标与口径!$H$5:$H$36,MATCH("order_accuracy",目标与口径!$A$5:$A$36,0)) -> 0.99 | G16: =IFERROR(MAX(0,IF(INDEX(目标与口径!$E$5:$E$36,MATCH("order_accuracy",目标与口径!$A$5:$A$36,0))="越高越好",INDEX(目标与口径!$G$5:$G$36,MATCH("order_accuracy",目标与口径!$A$5:$A$36,0))-$B$16,$B$16-INDEX(目标与口径!$G$5:$G$36,MATCH("order_accuracy",目标与口径!$A$5:$A$36,0)))/ABS(INDEX(目标与口径!$H$5:$H$36,MATCH("order_accuracy",目标与口径!$A$5:$A$36,0))-INDEX(目标与口径!$G$5:$G$36,MATCH("order_accuracy",目标与口径!$A$5:$A$36,0)))),0) -> 0 | H16: =INDEX(目标与口径!$J$5:$J$36,MATCH("order_accuracy",目标与口径!$A$5:$A$36,0)) -> 值班经理 | I16: =INDEX(目标与口径!$N$5:$N$36,MATCH("order_accuracy",目标与口径!$A$5:$A$36,0)) -> PB-05
A17: 食安日检得分 | B17: =IFERROR(INDEX(每日经营日报!$AM$5:$AM$18,MATCH($B$3,每日经营日报!$A$5:$A$18,0)),0) -> 100 | C17: =INDEX(目标与口径!$F$5:$F$36,MATCH("food_safety_score",目标与口径!$A$5:$A$36,0)) -> 100 | D17: =IFERROR(IF(INDEX(目标与口径!$E$5:$E$36,MATCH("food_safety_score",目标与口径!$A$5:$A$36,0))="越高越好",IF($B$17>=INDEX(目标与口径!$G$5:$G$36,MATCH("food_safety_score",目标与口径!$A$5:$A$36,0)),"绿",IF($B$17>=INDEX(目标与口径!$H$5:$H$36,MATCH("food_safety_score",目标与口径!$A$5:$A$36,0)),"黄","红")),IF($B$17<=INDEX(目标与口径!$G$5:$G$36,MATCH("food_safety_score",目标与口径!$A$5:$A$36,0)),"绿",IF($B$17<=INDEX(目标与口径!$H$5:$H$36,MATCH("food_safety_score",目标与口径!$A$5:$A$36,0)),"黄","红"))),"—") -> 绿 | E17: =INDEX(目标与口径!$G$5:$G$36,MATCH("food_safety_score",目标与口径!$A$5:$A$36,0)) -> 98 | F17: =INDEX(目标与口径!$H$5:$H$36,MATCH("food_safety_score",目标与口径!$A$5:$A$36,0)) -> 95 | G17: =IFERROR(MAX(0,IF(INDEX(目标与口径!$E$5:$E$36,MATCH("food_safety_score",目标与口径!$A$5:$A$36,0))="越高越好",INDEX(目标与口径!$G$5:$G$36,MATCH("food_safety_score",目标与口径!$A$5:$A$36,0))-$B$17,$B$17-INDEX(目标与口径!$G$5:$G$36,MATCH("food_safety_score",目标与口径!$A$5:$A$36,0)))/ABS(INDEX(目标与口径!$H$5:$H$36,MATCH("food_safety_score",目标与口径!$A$5:$A$36,0))-INDEX(目标与口径!$G$5:$G$36,MATCH("food_safety_score",目标与口径!$A$5:$A$36,0)))),0) -> 0 | H17: =INDEX(目标与口径!$J$5:$J$36,MATCH("food_safety_score",目标与口径!$A$5:$A$36,0)) -> 店长 | I17: =INDEX(目标与口径!$N$5:$N$36,MATCH("food_safety_score",目标与口径!$A$5:$A$36,0)) -> PB-09
A18: 关键温度点异常数 | B18: =IFERROR(INDEX(每日经营日报!$AN$5:$AN$18,MATCH($B$3,每日经营日报!$A$5:$A$18,0)),0) -> 0 | C18: =INDEX(目标与口径!$F$5:$F$36,MATCH("critical_temp_fail",目标与口径!$A$5:$A$36,0)) -> 0 | D18: =IFERROR(IF(INDEX(目标与口径!$E$5:$E$36,MATCH("critical_temp_fail",目标与口径!$A$5:$A$36,0))="越高越好",IF($B$18>=INDEX(目标与口径!$G$5:$G$36,MATCH("critical_temp_fail",目标与口径!$A$5:$A$36,0)),"绿",IF($B$18>=INDEX(目标与口径!$H$5:$H$36,MATCH("critical_temp_fail",目标与口径!$A$5:$A$36,0)),"黄","红")),IF($B$18<=INDEX(目标与口径!$G$5:$G$36,MATCH("critical_temp_fail",目标与口径!$A$5:$A$36,0)),"绿",IF($B$18<=INDEX(目标与口径!$H$5:$H$36,MATCH("critical_temp_fail",目标与口径!$A$5:$A$36,0)),"黄","红"))),"—") -> 绿 | E18: =INDEX(目标与口径!$G$5:$G$36,MATCH("critical_temp_fail",目标与口径!$A$5:$A$36,0)) -> 0 | F18: =INDEX(目标与口径!$H$5:$H$36,MATCH("critical_temp_fail",目标与口径!$A$5:$A$36,0)) -> 1 | G18: =IFERROR(MAX(0,IF(INDEX(目标与口径!$E$5:$E$36,MATCH("critical_temp_fail",目标与口径!$A$5:$A$36,0))="越高越好",INDEX(目标与口径!$G$5:$G$36,MATCH("critical_temp_fail",目标与口径!$A$5:$A$36,0))-$B$18,$B$18-INDEX(目标与口径!$G$5:$G$36,MATCH("critical_temp_fail",目标与口径!$A$5:$A$36,0)))/ABS(INDEX(目标与口径!$H$5:$H$36,MATCH("critical_temp_fail",目标与口径!$A$5:$A$36,0))-INDEX(目标与口径!$G$5:$G$36,MATCH("critical_temp_fail",目标与口径!$A$5:$A$36,0)))),0) -> 0 | H18: =INDEX(目标与口径!$J$5:$J$36,MATCH("critical_temp_fail",目标与口径!$A$5:$A$36,0)) -> 值班经理 | I18: =INDEX(目标与口径!$N$5:$N$36,MATCH("critical_temp_fail",目标与口径!$A$5:$A$36,0)) -> PB-09
A19: 设备停机时长 | B19: =IFERROR(INDEX(每日经营日报!$AS$5:$AS$18,MATCH($B$3,每日经营日报!$A$5:$A$18,0)),0) -> 76 | C19: =INDEX(目标与口径!$F$5:$F$36,MATCH("equipment_downtime",目标与口径!$A$5:$A$36,0)) -> 0 | D19: =IFERROR(IF(INDEX(目标与口径!$E$5:$E$36,MATCH("equipment_downtime",目标与口径!$A$5:$A$36,0))="越高越好",IF($B$19>=INDEX(目标与口径!$G$5:$G$36,MATCH("equipment_downtime",目标与口径!$A$5:$A$36,0)),"绿",IF($B$19>=INDEX(目标与口径!$H$5:$H$36,MATCH("equipment_downtime",目标与口径!$A$5:$A$36,0)),"黄","红")),IF($B$19<=INDEX(目标与口径!$G$5:$G$36,MATCH("equipment_downtime",目标与口径!$A$5:$A$36,0)),"绿",IF($B$19<=INDEX(目标与口径!$H$5:$H$36,MATCH("equipment_downtime",目标与口径!$A$5:$A$36,0)),"黄","红"))),"—") -> 红 | E19: =INDEX(目标与口径!$G$5:$G$36,MATCH("equipment_downtime",目标与口径!$A$5:$A$36,0)) -> 15 | F19: =INDEX(目标与口径!$H$5:$H$36,MATCH("equipment_downtime",目标与口径!$A$5:$A$36,0)) -> 60 | G19: =IFERROR(MAX(0,IF(INDEX(目标与口径!$E$5:$E$36,MATCH("equipment_downtime",目标与口径!$A$5:$A$36,0))="越高越好",INDEX(目标与口径!$G$5:$G$36,MATCH("equipment_downtime",目标与口径!$A$5:$A$36,0))-$B$19,$B$19-INDEX(目标与口径!$G$5:$G$36,MATCH("equipment_downtime",目标与口径!$A$5:$A$36,0)))/ABS(INDEX(目标与口径!$H$5:$H$36,MATCH("equipment_downtime",目标与口径!$A$5:$A$36,0))-INDEX(目标与口径!$G$5:$G$36,MATCH("equipment_downtime",目标与口径!$A$5:$A$36,0)))),0) -> 1.3555556 | H19: =INDEX(目标与口径!$J$5:$J$36,MATCH("equipment_downtime",目标与口径!$A$5:$A$36,0)) -> 店长 | I19: =INDEX(目标与口径!$N$5:$N$36,MATCH("equipment_downtime",目标与口径!$A$5:$A$36,0)) -> PB-11
A20: 出勤达成率 | B20: =IFERROR(INDEX(每日经营日报!$AV$5:$AV$18,MATCH($B$3,每日经营日报!$A$5:$A$18,0)),0) -> 1 | C20: =INDEX(目标与口径!$F$5:$F$36,MATCH("attendance_rate",目标与口径!$A$5:$A$36,0)) -> 1 | D20: =IFERROR(IF(INDEX(目标与口径!$E$5:$E$36,MATCH("attendance_rate",目标与口径!$A$5:$A$36,0))="越高越好",IF($B$20>=INDEX(目标与口径!$G$5:$G$36,MATCH("attendance_rate",目标与口径!$A$5:$A$36,0)),"绿",IF($B$20>=INDEX(目标与口径!$H$5:$H$36,MATCH("attendance_rate",目标与口径!$A$5:$A$36,0)),"黄","红")),IF($B$20<=INDEX(目标与口径!$G$5:$G$36,MATCH("attendance_rate",目标与口径!$A$5:$A$36,0)),"绿",IF($B$20<=INDEX(目标与口径!$H$5:$H$36,MATCH("attendance_rate",目标与口径!$A$5:$A$36,0)),"黄","红"))),"—") -> 绿 | E20: =INDEX(目标与口径!$G$5:$G$36,MATCH("attendance_rate",目标与口径!$A$5:$A$36,0)) -> 0.97 | F20: =INDEX(目标与口径!$H$5:$H$36,MATCH("attendance_rate",目标与口径!$A$5:$A$36,0)) -> 0.92 | G20: =IFERROR(MAX(0,IF(INDEX(目标与口径!$E$5:$E$36,MATCH("attendance_rate",目标与口径!$A$5:$A$36,0))="越高越好",INDEX(目标与口径!$G$5:$G$36,MATCH("attendance_rate",目标与口径!$A$5:$A$36,0))-$B$20,$B$20-INDEX(目标与口径!$G$5:$G$36,MATCH("attendance_rate",目标与口径!$A$5:$A$36,0)))/ABS(INDEX(目标与口径!$H$5:$H$36,MATCH("attendance_rate",目标与口径!$A$5:$A$36,0))-INDEX(目标与口径!$G$5:$G$36,MATCH("attendance_rate",目标与口径!$A$5:$A$36,0)))),0) -> 0 | H20: =INDEX(目标与口径!$J$5:$J$36,MATCH("attendance_rate",目标与口径!$A$5:$A$36,0)) -> 值班经理 | I20: =INDEX(目标与口径!$N$5:$N$36,MATCH("attendance_rate",目标与口径!$A$5:$A$36,0)) -> PB-07
A21: 迟到率 | B21: =IFERROR(INDEX(每日经营日报!$AX$5:$AX$18,MATCH($B$3,每日经营日报!$A$5:$A$18,0)),0) -> 0.10526316 | C21: =INDEX(目标与口径!$F$5:$F$36,MATCH("late_rate",目标与口径!$A$5:$A$36,0)) -> 0.02 | D21: =IFERROR(IF(INDEX(目标与口径!$E$5:$E$36,MATCH("late_rate",目标与口径!$A$5:$A$36,0))="越高越好",IF($B$21>=INDEX(目标与口径!$G$5:$G$36,MATCH("late_rate",目标与口径!$A$5:$A$36,0)),"绿",IF($B$21>=INDEX(目标与口径!$H$5:$H$36,MATCH("late_rate",目标与口径!$A$5:$A$36,0)),"黄","红")),IF($B$21<=INDEX(目标与口径!$G$5:$G$36,MATCH("late_rate",目标与口径!$A$5:$A$36,0)),"绿",IF($B$21<=INDEX(目标与口径!$H$5:$H$36,MATCH("late_rate",目标与口径!$A$5:$A$36,0)),"黄","红"))),"—") -> 红 | E21: =INDEX(目标与口径!$G$5:$G$36,MATCH("late_rate",目标与口径!$A$5:$A$36,0)) -> 0.03 | F21: =INDEX(目标与口径!$H$5:$H$36,MATCH("late_rate",目标与口径!$A$5:$A$36,0)) -> 0.08 | G21: =IFERROR(MAX(0,IF(INDEX(目标与口径!$E$5:$E$36,MATCH("late_rate",目标与口径!$A$5:$A$36,0))="越高越好",INDEX(目标与口径!$G$5:$G$36,MATCH("late_rate",目标与口径!$A$5:$A$36,0))-$B$21,$B$21-INDEX(目标与口径!$G$5:$G$36,MATCH("late_rate",目标与口径!$A$5:$A$36,0)))/ABS(INDEX(目标与口径!$H$5:$H$36,MATCH("late_rate",目标与口径!$A$5:$A$36,0))-INDEX(目标与口径!$G$5:$G$36,MATCH("late_rate",目标与口径!$A$5:$A$36,0)))),0) -> 1.5052632 | H21: =INDEX(目标与口径!$J$5:$J$36,MATCH("late_rate",目标与口径!$A$5:$A$36,0)) -> 组长 | I21: =INDEX(目标与口径!$N$5:$N$36,MATCH("late_rate",目标与口径!$A$5:$A$36,0)) -> PB-07
A22: 顾客满意度 | B22: =IFERROR(INDEX(每日经营日报!$BD$5:$BD$18,MATCH($B$3,每日经营日报!$A$5:$A$18,0)),0) -> 92.571429 | C22: =INDEX(目标与口径!$F$5:$F$36,MATCH("csat",目标与口径!$A$5:$A$36,0)) -> 88 | D22: =IFERROR(IF(INDEX(目标与口径!$E$5:$E$36,MATCH("csat",目标与口径!$A$5:$A$36,0))="越高越好",IF($B$22>=INDEX(目标与口径!$G$5:$G$36,MATCH("csat",目标与口径!$A$5:$A$36,0)),"绿",IF($B$22>=INDEX(目标与口径!$H$5:$H$36,MATCH("csat",目标与口径!$A$5:$A$36,0)),"黄","红")),IF($B$22<=INDEX(目标与口径!$G$5:$G$36,MATCH("csat",目标与口径!$A$5:$A$36,0)),"绿",IF($B$22<=INDEX(目标与口径!$H$5:$H$36,MATCH("csat",目标与口径!$A$5:$A$36,0)),"黄","红"))),"—") -> 绿 | E22: =INDEX(目标与口径!$G$5:$G$36,MATCH("csat",目标与口径!$A$5:$A$36,0)) -> 85 | F22: =INDEX(目标与口径!$H$5:$H$36,MATCH("csat",目标与口径!$A$5:$A$36,0)) -> 78 | G22: =IFERROR(MAX(0,IF(INDEX(目标与口径!$E$5:$E$36,MATCH("csat",目标与口径!$A$5:$A$36,0))="越高越好",INDEX(目标与口径!$G$5:$G$36,MATCH("csat",目标与口径!$A$5:$A$36,0))-$B$22,$B$22-INDEX(目标与口径!$G$5:$G$36,MATCH("csat",目标与口径!$A$5:$A$36,0)))/ABS(INDEX(目标与口径!$H$5:$H$36,MATCH("csat",目标与口径!$A$5:$A$36,0))-INDEX(目标与口径!$G$5:$G$36,MATCH("csat",目标与口径!$A$5:$A$36,0)))),0) -> 0 | H22: =INDEX(目标与口径!$J$5:$J$36,MATCH("csat",目标与口径!$A$5:$A$36,0)) -> 店长 | I22: =INDEX(目标与口径!$N$5:$N$36,MATCH("csat",目标与口径!$A$5:$A$36,0)) -> PB-05
A23: 外卖平台评分 | B23: =IFERROR(INDEX(每日经营日报!$BE$5:$BE$18,MATCH($B$3,每日经营日报!$A$5:$A$18,0)),0) -> 4.1375 | C23: =INDEX(目标与口径!$F$5:$F$36,MATCH("delivery_rating",目标与口径!$A$5:$A$36,0)) -> 4.8 | D23: =IFERROR(IF(INDEX(目标与口径!$E$5:$E$36,MATCH("delivery_rating",目标与口径!$A$5:$A$36,0))="越高越好",IF($B$23>=INDEX(目标与口径!$G$5:$G$36,MATCH("delivery_rating",目标与口径!$A$5:$A$36,0)),"绿",IF($B$23>=INDEX(目标与口径!$H$5:$H$36,MATCH("delivery_rating",目标与口径!$A$5:$A$36,0)),"黄","红")),IF($B$23<=INDEX(目标与口径!$G$5:$G$36,MATCH("delivery_rating",目标与口径!$A$5:$A$36,0)),"绿",IF($B$23<=INDEX(目标与口径!$H$5:$H$36,MATCH("delivery_rating",目标与口径!$A$5:$A$36,0)),"黄","红"))),"—") -> 红 | E23: =INDEX(目标与口径!$G$5:$G$36,MATCH("delivery_rating",目标与口径!$A$5:$A$36,0)) -> 4.7 | F23: =INDEX(目标与口径!$H$5:$H$36,MATCH("delivery_rating",目标与口径!$A$5:$A$36,0)) -> 4.5 | G23: =IFERROR(MAX(0,IF(INDEX(目标与口径!$E$5:$E$36,MATCH("delivery_rating",目标与口径!$A$5:$A$36,0))="越高越好",INDEX(目标与口径!$G$5:$G$36,MATCH("delivery_rating",目标与口径!$A$5:$A$36,0))-$B$23,$B$23-INDEX(目标与口径!$G$5:$G$36,MATCH("delivery_rating",目标与口径!$A$5:$A$36,0)))/ABS(INDEX(目标与口径!$H$5:$H$36,MATCH("delivery_rating",目标与口径!$A$5:$A$36,0))-INDEX(目标与口径!$G$5:$G$36,MATCH("delivery_rating",目标与口径!$A$5:$A$36,0)))),0) -> 2.8125 | H23: =INDEX(目标与口径!$J$5:$J$36,MATCH("delivery_rating",目标与口径!$A$5:$A$36,0)) -> 店长 | I23: =INDEX(目标与口径!$N$5:$N$36,MATCH("delivery_rating",目标与口径!$A$5:$A$36,0)) -> PB-03
A25: B. 六个家族的灯（绿 / 黄 / 红 计数）
A26: 家族 | B26: 绿 | C26: 黄 | D26: 红 | E26: 状态
A27: 生意 | B27: =COUNTIF(($D$6~$D$7~$D$8~$D$9),"绿") -> 1 | C27: =COUNTIF(($D$6~$D$7~$D$8~$D$9),"黄") -> 3 | D27: =COUNTIF(($D$6~$D$7~$D$8~$D$9),"红") -> 0 | E27: =IF(D27>0,"红",IF(C27>0,"黄","绿")) -> 黄
A28: 速度 | B28: =COUNTIF(($D$14~$D$15~$D$16),"绿") -> 2 | C28: =COUNTIF(($D$14~$D$15~$D$16),"黄") -> 0 | D28: =COUNTIF(($D$14~$D$15~$D$16),"红") -> 1 | E28: =IF(D28>0,"红",IF(C28>0,"黄","绿")) -> 红
A29: 成本 | B29: =COUNTIF(($D$10~$D$11~$D$12~$D$13),"绿") -> 2 | C29: =COUNTIF(($D$10~$D$11~$D$12~$D$13),"黄") -> 2 | D29: =COUNTIF(($D$10~$D$11~$D$12~$D$13),"红") -> 0 | E29: =IF(D29>0,"红",IF(C29>0,"黄","绿")) -> 黄
A30: 品质与食安 | B30: =COUNTIF(($D$17~$D$18~$D$19),"绿") -> 2 | C30: =COUNTIF(($D$17~$D$18~$D$19),"黄") -> 0 | D30: =COUNTIF(($D$17~$D$18~$D$19),"红") -> 1 | E30: =IF(D30>0,"红",IF(C30>0,"黄","绿")) -> 红
A31: 人员 | B31: =COUNTIF(($D$20~$D$21),"绿") -> 1 | C31: =COUNTIF(($D$20~$D$21),"黄") -> 0 | D31: =COUNTIF(($D$20~$D$21),"红") -> 1 | E31: =IF(D31>0,"红",IF(C31>0,"黄","绿")) -> 红
A32: 顾客 | B32: =COUNTIF(($D$22~$D$23),"绿") -> 1 | C32: =COUNTIF(($D$22~$D$23),"黄") -> 0 | D32: =COUNTIF(($D$22~$D$23),"红") -> 1 | E32: =IF(D32>0,"红",IF(C32>0,"黄","绿")) -> 红
A34: C. 今天的三件事（取「优先级矩阵」行动分最高的三项，公式动态排名）
A35: # | B35: 指标 | C35: 最新值 | D35: 状态 | E35: 象限 | F35: 责任人 | G35: 行动卡 | H35: 行动分 | I35: 第一动作
A36: 1 | B36: =IFERROR(INDEX(优先级矩阵!$B$5:$B$36,MATCH(LARGE(优先级矩阵!$J$5:$J$36,1),优先级矩阵!$J$5:$J$36,0)),"") -> 外卖平台评分 | C36: =IFERROR(INDEX(优先级矩阵!$C$5:$C$36,MATCH(LARGE(优先级矩阵!$J$5:$J$36,1),优先级矩阵!$J$5:$J$36,0)),"") -> 4.1375 | D36: =IFERROR(INDEX(优先级矩阵!$E$5:$E$36,MATCH(LARGE(优先级矩阵!$J$5:$J$36,1),优先级矩阵!$J$5:$J$36,0)),"") -> 红 | E36: =IFERROR(INDEX(优先级矩阵!$H$5:$H$36,MATCH(LARGE(优先级矩阵!$J$5:$J$36,1),优先级矩阵!$J$5:$J$36,0)),"") -> Q2 上报求援 | F36: =IFERROR(INDEX(优先级矩阵!$I$5:$I$36,MATCH(LARGE(优先级矩阵!$J$5:$J$36,1),优先级矩阵!$J$5:$J$36,0)),"") -> 店长 | G36: =IFERROR(INDEX(优先级矩阵!$K$5:$K$36,MATCH(LARGE(优先级矩阵!$J$5:$J$36,1),优先级矩阵!$J$5:$J$36,0)),"") -> PB-03 | H36: =IFERROR(INDEX(优先级矩阵!$J$5:$J$36,MATCH(LARGE(优先级矩阵!$J$5:$J$36,1),优先级矩阵!$J$5:$J$36,0)),"") -> 2.17 | I36: =IFERROR(INDEX(优先级矩阵!$L$5:$L$36,MATCH(LARGE(优先级矩阵!$J$5:$J$36,1),优先级矩阵!$J$5:$J$36,0)),"") -> 全时段慢=打包流程问题（上报）；只高峰慢=给外送单独留打包位
A37: 2 | B37: =IFERROR(INDEX(优先级矩阵!$B$5:$B$36,MATCH(LARGE(优先级矩阵!$J$5:$J$36,2),优先级矩阵!$J$5:$J$36,0)),"") -> 服务速度达标率 | C37: =IFERROR(INDEX(优先级矩阵!$C$5:$C$36,MATCH(LARGE(优先级矩阵!$J$5:$J$36,2),优先级矩阵!$J$5:$J$36,0)),"") -> 0.76598465 | D37: =IFERROR(INDEX(优先级矩阵!$E$5:$E$36,MATCH(LARGE(优先级矩阵!$J$5:$J$36,2),优先级矩阵!$J$5:$J$36,0)),"") -> 红 | E37: =IFERROR(INDEX(优先级矩阵!$H$5:$H$36,MATCH(LARGE(优先级矩阵!$J$5:$J$36,2),优先级矩阵!$J$5:$J$36,0)),"") -> Q1 今天就做 | F37: =IFERROR(INDEX(优先级矩阵!$I$5:$I$36,MATCH(LARGE(优先级矩阵!$J$5:$J$36,2),优先级矩阵!$J$5:$J$36,0)),"") -> 值班经理 | G37: =IFERROR(INDEX(优先级矩阵!$K$5:$K$36,MATCH(LARGE(优先级矩阵!$J$5:$J$36,2),优先级矩阵!$J$5:$J$36,0)),"") -> PB-04 | H37: =IFERROR(INDEX(优先级矩阵!$J$5:$J$36,MATCH(LARGE(优先级矩阵!$J$5:$J$36,2),优先级矩阵!$J$5:$J$36,0)),"") -> 2.06 | I37: =IFERROR(INDEX(优先级矩阵!$L$5:$L$36,MATCH(LARGE(优先级矩阵!$J$5:$J$36,2),优先级矩阵!$J$5:$J$36,0)),"") -> 先分段定位（点单/排队/取餐窗/制作），再看是结构问题还是产能问题
A38: 3 | B38: =IFERROR(INDEX(优先级矩阵!$B$5:$B$36,MATCH(LARGE(优先级矩阵!$J$5:$J$36,3),优先级矩阵!$J$5:$J$36,0)),"") -> 迟到率 | C38: =IFERROR(INDEX(优先级矩阵!$C$5:$C$36,MATCH(LARGE(优先级矩阵!$J$5:$J$36,3),优先级矩阵!$J$5:$J$36,0)),"") -> 0.10526316 | D38: =IFERROR(INDEX(优先级矩阵!$E$5:$E$36,MATCH(LARGE(优先级矩阵!$J$5:$J$36,3),优先级矩阵!$J$5:$J$36,0)),"") -> 红 | E38: =IFERROR(INDEX(优先级矩阵!$H$5:$H$36,MATCH(LARGE(优先级矩阵!$J$5:$J$36,3),优先级矩阵!$J$5:$J$36,0)),"") -> Q3 顺手做掉 | F38: =IFERROR(INDEX(优先级矩阵!$I$5:$I$36,MATCH(LARGE(优先级矩阵!$J$5:$J$36,3),优先级矩阵!$J$5:$J$36,0)),"") -> 组长 | G38: =IFERROR(INDEX(优先级矩阵!$K$5:$K$36,MATCH(LARGE(优先级矩阵!$J$5:$J$36,3),优先级矩阵!$J$5:$J$36,0)),"") -> PB-07 | H38: =IFERROR(INDEX(优先级矩阵!$J$5:$J$36,MATCH(LARGE(优先级矩阵!$J$5:$J$36,3),优先级矩阵!$J$5:$J$36,0)),"") -> 1.02 | I38: =IFERROR(INDEX(优先级矩阵!$L$5:$L$36,MATCH(LARGE(优先级矩阵!$J$5:$J$36,3),优先级矩阵!$J$5:$J$36,0)),"") -> 看 SPLH 与速度的组合：都差 = 排班结构错，调岗位不是加人头
A40: 「最新值」= 从「每日经营日报」按 B3 的日期取当天的数；「目标/绿线/黄线/责任人/行动卡」= 从「目标与口径」按指标ID 回查；「超线带宽」= 越过绿线几个黄灯带宽（(绿线−实际)÷|黄线−绿线|），用来在不同量纲的指标之间排优先级——不能用相对偏差，否则目标 2% 的迟到率会天天霸占第一。

Sheet 每日经营日报
A1: 每日经营日报 · Daily Operations Report
A2: 一行一天。浅蓝色是每天要填的原子数，白色是公式（客单价、各类比率、SPLH 等）自动计算。改任何一个浅蓝格子，右边的派生列和「店长看板」会一起更新。
A4: 日期 | B4: 星期 | C4: 销售预测 | D4: 净销售额 | E4: 交易笔数 | F4: 客单价 | G4: 销售达成率 | H4: 商品件数 | I4: 单均件数 | J4: 数字渠道占比 | K4: 外送销售额 | L4: 外送占比 | M4: 人工点单数 | N4: 附加销售单数 | O4: 附加销售率 | P4: 食品成本额 | Q4: 食品成本率 | R4: 废弃金额 | S4: 废弃率 | T4: 实际工时 | U4: 计划工时 | V4: 平均时薪 | W4: 班组计划工时 | X4: 班组实际工时 | Y4: 人工成本 | Z4: 人工成本率 | AA4: 人时销售SPLH | AB4: 工时排班偏差 | AC4: 得来速总时长 | AD4: 得来速取餐窗 | AE4: 后厨制作时长 | AF4: 前台交付OTD | AG4: 外送出餐时长 | AH4: 达标订单数 | AI4: 服务速度达标率 | AJ4: 差错事件数 | AK4: 订单准确率 | AL4: 千单投诉数 | AM4: 食安日检得分 | AN4: 关键温度异常 | AO4: 保温批次数 | AP4: 保温废弃数 | AQ4: 保温超时率 | AR4: 清洁巡检得分 | AS4: 设备停机分钟 | AT4: 排班人次 | AU4: 到岗人次 | AV4: 出勤达成率 | AW4: 迟到人次 | AX4: 迟到率 | AY4: 认证人次 | AZ4: 岗位认证覆盖率 | BA4: 30日流失率 | BB4: 调研总分 | BC4: 调研份数 | BD4: 顾客满意度 | BE4: 外卖平台评分 | BF4: 现金短溢 | BG4: 店长备注
A5: 46239 | B5: =TEXT(A5,"aaa") -> Wed | C5: 61806.75 | D5: 60215.69 | E5: 1661 | F5: =IFERROR(D5/E5,0) -> 36.252673 | G5: =IFERROR(D5/C5,0) -> 0.9742575 | H5: 5624 | I5: =IFERROR(H5/E5,0) -> 3.3859121 | J5: 0.64057797 | K5: 16257.27 | L5: =IFERROR(K5/D5,0) -> 0.26998395 | M5: 597 | N5: 143 | O5: =IFERROR(N5/M5,0) -> 0.23953099 | P5: 18573.69 | Q5: =IFERROR(P5/D5,0) -> 0.30845266 | R5: 646.87 | S5: =IFERROR(R5/D5,0) -> 0.010742549 | T5: 271.72 | U5: 282.5 | V5: 28.5 | W5: 248.5 | X5: 237.7225 | Y5: =T5*V5 -> 7744.02 | Z5: =IFERROR(Y5/D5,0) -> 0.12860469 | AA5: =IFERROR(D5/T5,0) -> 221.60934 | AB5: =IFERROR(ABS(X5-W5)/W5,0) -> 0.043370221 | AC5: 156.87 | AD5: 58.06 | AE5: 86.39 | AF5: 128.96 | AG5: 418.23 | AH5: 1259 | AI5: =IFERROR(AH5/E5,0) -> 0.75797712 | AJ5: 4 | AK5: =IFERROR(1-AJ5/E5,0) -> 0.99759181 | AL5: =IFERROR(AJ5/E5*1000,0) -> 2.4081878 | AM5: 99.333 | AN5: 0 | AO5: 2160 | AP5: 64 | AQ5: =IFERROR(AP5/AO5,0) -> 0.02962963 | AR5: 91.4 | AS5: 0 | AT5: 40 | AU5: 40 | AV5: =IFERROR(AU5/AT5,0) -> 1 | AW5: 3 | AX5: =IFERROR(AW5/AU5,0) -> 0.075 | AY5: 34 | AZ5: =IFERROR(AY5/AT5,0) -> 0.85 | BA5: 0.10769231 | BB5: 133 | BC5: 30 | BD5: =IFERROR(BB5/BC5*20,0) -> 88.666667 | BE5: 4.1332 | BF5: 37.25
A6: 46240 | B6: =TEXT(A6,"aaa") -> Thu | C6: 57823.97 | D6: 55843.81 | E6: 1565 | F6: =IFERROR(D6/E6,0) -> 35.682946 | G6: =IFERROR(D6/C6,0) -> 0.96575538 | H6: 5232 | I6: =IFERROR(H6/E6,0) -> 3.343131 | J6: 0.63258786 | K6: 14190.62 | L6: =IFERROR(K6/D6,0) -> 0.25411268 | M6: 575 | N6: 126 | O6: =IFERROR(N6/M6,0) -> 0.21913043 | P6: 17096.37 | Q6: =IFERROR(P6/D6,0) -> 0.3061462 | R6: 628.62 | S6: =IFERROR(R6/D6,0) -> 0.011256753 | T6: 260.44 | U6: 272.55 | V6: 28.5 | W6: 238.55 | X6: 226.4375 | Y6: =T6*V6 -> 7422.54 | Z6: =IFERROR(Y6/D6,0) -> 0.13291607 | AA6: =IFERROR(D6/T6,0) -> 214.42102 | AB6: =IFERROR(ABS(X6-W6)/W6,0) -> 0.050775519 | AC6: 155.6 | AD6: 58.33 | AE6: 86.49 | AF6: 128.76 | AG6: 415.58 | AH6: 1225 | AI6: =IFERROR(AH6/E6,0) -> 0.7827476 | AJ6: 3 | AK6: =IFERROR(1-AJ6/E6,0) -> 0.99808307 | AL6: =IFERROR(AJ6/E6*1000,0) -> 1.9169329 | AM6: 98 | AN6: 0 | AO6: 1995 | AP6: 46 | AQ6: =IFERROR(AP6/AO6,0) -> 0.023057644 | AR6: 91.667 | AS6: 38 | AT6: 38 | AU6: 34 | AV6: =IFERROR(AU6/AT6,0) -> 0.89473684 | AW6: 5 | AX6: =IFERROR(AW6/AU6,0) -> 0.14705882 | AY6: 37 | AZ6: =IFERROR(AY6/AT6,0) -> 0.97368421 | BA6: 0.10769231 | BB6: 154 | BC6: 35 | BD6: =IFERROR(BB6/BC6*20,0) -> 88 | BE6: 4.0907 | BF6: 34.76
A7: 46241 | B7: =TEXT(A7,"aaa") -> Fri | C7: 75744.98 | D7: 74500.09 | E7: 2067 | F7: =IFERROR(D7/E7,0) -> 36.042617 | G7: =IFERROR(D7/C7,0) -> 0.98356472 | H7: 6949 | I7: =IFERROR(H7/E7,0) -> 3.3618771 | J7: 0.63812288 | K7: 20532.42 | L7: =IFERROR(K7/D7,0) -> 0.27560262 | M7: 748 | N7: 163 | O7: =IFERROR(N7/M7,0) -> 0.21791444 | P7: 22878.77 | Q7: =IFERROR(P7/D7,0) -> 0.30709721 | R7: 797.43 | S7: =IFERROR(R7/D7,0) -> 0.010703745 | T7: 313.86 | U7: 324.85 | V7: 28.5 | W7: 290.85 | X7: 279.865 | Y7: =T7*V7 -> 8945.01 | Z7: =IFERROR(Y7/D7,0) -> 0.1200671 | AA7: =IFERROR(D7/T7,0) -> 237.36727 | AB7: =IFERROR(ABS(X7-W7)/W7,0) -> 0.037768609 | AC7: 157.68 | AD7: 58.66 | AE7: 88.07 | AF7: 132.14 | AG7: 425.23 | AH7: 1492 | AI7: =IFERROR(AH7/E7,0) -> 0.72181906 | AJ7: 2 | AK7: =IFERROR(1-AJ7/E7,0) -> 0.99903241 | AL7: =IFERROR(AJ7/E7*1000,0) -> 0.96758587 | AM7: 99.333 | AN7: 0 | AO7: 2767 | AP7: 73 | AQ7: =IFERROR(AP7/AO7,0) -> 0.026382364 | AR7: 91.533 | AS7: 0 | AT7: 47 | AU7: 46 | AV7: =IFERROR(AU7/AT7,0) -> 0.9787234 | AW7: 5 | AX7: =IFERROR(AW7/AU7,0) -> 0.10869565 | AY7: 43 | AZ7: =IFERROR(AY7/AT7,0) -> 0.91489362 | BA7: 0.092307692 | BB7: 230 | BC7: 51 | BD7: =IFERROR(BB7/BC7*20,0) -> 90.196078 | BE7: 4.0245 | BF7: 40.77
A8: 46242 | B8: =TEXT(A8,"aaa") -> Sat | C8: 82007.96 | D8: 80843.72 | E8: 2248 | F8: =IFERROR(D8/E8,0) -> 35.962509 | G8: =IFERROR(D8/C8,0) -> 0.98580333 | H8: 7533 | I8: =IFERROR(H8/E8,0) -> 3.3509786 | J8: 0.63745552 | K8: 21337.65 | L8: =IFERROR(K8/D8,0) -> 0.26393701 | M8: 815 | N8: 193 | O8: =IFERROR(N8/M8,0) -> 0.23680982 | P8: 25050.68 | Q8: =IFERROR(P8/D8,0) -> 0.3098655 | R8: 934.38 | S8: =IFERROR(R8/D8,0) -> 0.011557855 | T8: 331.65 | U8: 343.73 | V8: 28.5 | W8: 309.725 | X8: 297.645 | Y8: =T8*V8 -> 9452.025 | Z8: =IFERROR(Y8/D8,0) -> 0.11691724 | AA8: =IFERROR(D8/T8,0) -> 243.76216 | AB8: =IFERROR(ABS(X8-W8)/W8,0) -> 0.039002341 | AC8: 159.75 | AD8: 58.56 | AE8: 88.06 | AF8: 132.97 | AG8: 434.63 | AH8: 1618 | AI8: =IFERROR(AH8/E8,0) -> 0.71975089 | AJ8: 5 | AK8: =IFERROR(1-AJ8/E8,0) -> 0.9977758 | AL8: =IFERROR(AJ8/E8*1000,0) -> 2.2241993 | AM8: 98.667 | AN8: 4 | AO8: 3033 | AP8: 70 | AQ8: =IFERROR(AP8/AO8,0) -> 0.023079459 | AR8: 93.667 | AS8: 0 | AT8: 50 | AU8: 47 | AV8: =IFERROR(AU8/AT8,0) -> 0.94 | AW8: 2 | AX8: =IFERROR(AW8/AU8,0) -> 0.042553191 | AY8: 43 | AZ8: =IFERROR(AY8/AT8,0) -> 0.86 | BA8: 0.078125 | BB8: 188 | BC8: 41 | BD8: =IFERROR(BB8/BC8*20,0) -> 91.707317 | BE8: 4.0281 | BF8: 65.49
A9: 46243 | B9: =TEXT(A9,"aaa") -> Sun | C9: 72603.35 | D9: 71838.61 | E9: 1996 | F9: =IFERROR(D9/E9,0) -> 35.991288 | G9: =IFERROR(D9/C9,0) -> 0.98946688 | H9: 6719 | I9: =IFERROR(H9/E9,0) -> 3.3662325 | J9: 0.64679359 | K9: 18940.76 | L9: =IFERROR(K9/D9,0) -> 0.26365711 | M9: 705 | N9: 155 | O9: =IFERROR(N9/M9,0) -> 0.21985816 | P9: 22072.55 | Q9: =IFERROR(P9/D9,0) -> 0.30725191 | R9: 900.9 | S9: =IFERROR(R9/D9,0) -> 0.01254061 | T9: 305.96 | U9: 317.52 | V9: 28.5 | W9: 283.525 | X9: 271.955 | Y9: =T9*V9 -> 8719.86 | Z9: =IFERROR(Y9/D9,0) -> 0.12138125 | AA9: =IFERROR(D9/T9,0) -> 234.79739 | AB9: =IFERROR(ABS(X9-W9)/W9,0) -> 0.040807689 | AC9: 158.57 | AD9: 59.07 | AE9: 87.92 | AF9: 131.59 | AG9: 430.21 | AH9: 1482 | AI9: =IFERROR(AH9/E9,0) -> 0.74248497 | AJ9: 1 | AK9: =IFERROR(1-AJ9/E9,0) -> 0.999499 | AL9: =IFERROR(AJ9/E9*1000,0) -> 0.501002 | AM9: 99.333 | AN9: 0 | AO9: 2530 | AP9: 59 | AQ9: =IFERROR(AP9/AO9,0) -> 0.023320158 | AR9: 92.267 | AS9: 0 | AT9: 45 | AU9: 42 | AV9: =IFERROR(AU9/AT9,0) -> 0.93333333 | AW9: 5 | AX9: =IFERROR(AW9/AU9,0) -> 0.11904762 | AY9: 40 | AZ9: =IFERROR(AY9/AT9,0) -> 0.88888889 | BA9: 0.09375 | BB9: 187 | BC9: 42 | BD9: =IFERROR(BB9/BC9*20,0) -> 89.047619 | BE9: 4.0526 | BF9: 10.98
A10: 46244 | B10: =TEXT(A10,"aaa") -> Mon | C10: 56778.37 | D10: 56477.72 | E10: 1564 | F10: =IFERROR(D10/E10,0) -> 36.111074 | G10: =IFERROR(D10/C10,0) -> 0.99470485 | H10: 5249 | I10: =IFERROR(H10/E10,0) -> 3.3561381 | J10: 0.64641944 | K10: 15189.73 | L10: =IFERROR(K10/D10,0) -> 0.26895084 | M10: 553 | N10: 144 | O10: =IFERROR(N10/M10,0) -> 0.26039783 | P10: 17592.76 | Q10: =IFERROR(P10/D10,0) -> 0.31149912 | R10: 635.11 | S10: =IFERROR(R10/D10,0) -> 0.011245319 | T10: 261.91 | U10: 272.45 | V10: 28.5 | W10: 238.45 | X10: 227.9125 | Y10: =T10*V10 -> 7464.435 | Z10: =IFERROR(Y10/D10,0) -> 0.13216601 | AA10: =IFERROR(D10/T10,0) -> 215.63789 | AB10: =IFERROR(ABS(X10-W10)/W10,0) -> 0.044191654 | AC10: 152.63 | AD10: 56.02 | AE10: 85.39 | AF10: 126.8 | AG10: 419.83 | AH10: 1235 | AI10: =IFERROR(AH10/E10,0) -> 0.78964194 | AJ10: 0 | AK10: =IFERROR(1-AJ10/E10,0) -> 1 | AL10: =IFERROR(AJ10/E10*1000,0) -> 0 | AM10: 99.333 | AN10: 0 | AO10: 2049 | AP10: 41 | AQ10: =IFERROR(AP10/AO10,0) -> 0.020009761 | AR10: 88.667 | AS10: 0 | AT10: 38 | AU10: 35 | AV10: =IFERROR(AU10/AT10,0) -> 0.92105263 | AW10: 2 | AX10: =IFERROR(AW10/AU10,0) -> 0.057142857 | AY10: 30 | AZ10: =IFERROR(AY10/AT10,0) -> 0.78947368 | BA10: 0.063492063 | BB10: 110 | BC10: 24 | BD10: =IFERROR(BB10/BC10*20,0) -> 91.666667 | BE10: 4.1019 | BF10: 53.02
A11: 46245 | B11: =TEXT(A11,"aaa") -> Tue | C11: 55476.38 | D11: 53979.5 | E11: 1487 | F11: =IFERROR(D11/E11,0) -> 36.300941 | G11: =IFERROR(D11/C11,0) -> 0.97301771 | H11: 5009 | I11: =IFERROR(H11/E11,0) -> 3.3685272 | J11: 0.63483524 | K11: 14907.81 | L11: =IFERROR(K11/D11,0) -> 0.2761754 | M11: 543 | N11: 119 | O11: =IFERROR(N11/M11,0) -> 0.21915285 | P11: 16622.76 | Q11: =IFERROR(P11/D11,0) -> 0.30794579 | R11: 666.07 | S11: =IFERROR(R11/D11,0) -> 0.012339314 | T11: 252.77 | U11: 264.42 | V11: 28.5 | W11: 230.425 | X11: 218.7725 | Y11: =T11*V11 -> 7203.945 | Z11: =IFERROR(Y11/D11,0) -> 0.13345705 | AA11: =IFERROR(D11/T11,0) -> 213.55185 | AB11: =IFERROR(ABS(X11-W11)/W11,0) -> 0.0505696 | AC11: 153.37 | AD11: 56.68 | AE11: 85.31 | AF11: 127.24 | AG11: 413.62 | AH11: 1188 | AI11: =IFERROR(AH11/E11,0) -> 0.79892401 | AJ11: 2 | AK11: =IFERROR(1-AJ11/E11,0) -> 0.99865501 | AL11: =IFERROR(AJ11/E11*1000,0) -> 1.3449899 | AM11: 96.667 | AN11: 1 | AO11: 1808 | AP11: 43 | AQ11: =IFERROR(AP11/AO11,0) -> 0.023783186 | AR11: 94 | AS11: 0 | AT11: 36 | AU11: 36 | AV11: =IFERROR(AU11/AT11,0) -> 1 | AW11: 2 | AX11: =IFERROR(AW11/AU11,0) -> 0.055555556 | AY11: 33 | AZ11: =IFERROR(AY11/AT11,0) -> 0.91666667 | BA11: 0.063492063 | BB11: 170 | BC11: 38 | BD11: =IFERROR(BB11/BC11*20,0) -> 89.473684 | BE11: 4.1638 | BF11: 28.59
A12: 46246 | B12: =TEXT(A12,"aaa") -> Wed | C12: 57815.1 | D12: 57173.74 | E12: 1588 | F12: =IFERROR(D12/E12,0) -> 36.003615 | G12: =IFERROR(D12/C12,0) -> 0.9889067 | H12: 5323 | I12: =IFERROR(H12/E12,0) -> 3.3520151 | J12: 0.63287154 | K12: 15265.07 | L12: =IFERROR(K12/D12,0) -> 0.26699443 | M12: 583 | N12: 147 | O12: =IFERROR(N12/M12,0) -> 0.25214408 | P12: 17764.16 | Q12: =IFERROR(P12/D12,0) -> 0.31070488 | R12: 694.55 | S12: =IFERROR(R12/D12,0) -> 0.01214806 | T12: 264.38 | U12: 274.92 | V12: 28.5 | W12: 240.925 | X12: 230.3825 | Y12: =T12*V12 -> 7534.83 | Z12: =IFERROR(Y12/D12,0) -> 0.1317883 | AA12: =IFERROR(D12/T12,0) -> 216.25592 | AB12: =IFERROR(ABS(X12-W12)/W12,0) -> 0.043758431 | AC12: 154.07 | AD12: 57.08 | AE12: 86.31 | AF12: 129.92 | AG12: 412.56 | AH12: 1245 | AI12: =IFERROR(AH12/E12,0) -> 0.78400504 | AJ12: 2 | AK12: =IFERROR(1-AJ12/E12,0) -> 0.99874055 | AL12: =IFERROR(AJ12/E12*1000,0) -> 1.2594458 | AM12: 98 | AN12: 0 | AO12: 1992 | AP12: 46 | AQ12: =IFERROR(AP12/AO12,0) -> 0.023092369 | AR12: 90.333 | AS12: 0 | AT12: 38 | AU12: 34 | AV12: =IFERROR(AU12/AT12,0) -> 0.89473684 | AW12: 2 | AX12: =IFERROR(AW12/AU12,0) -> 0.058823529 | AY12: 35 | AZ12: =IFERROR(AY12/AT12,0) -> 0.92105263 | BA12: 0.048387097 | BB12: 184 | BC12: 41 | BD12: =IFERROR(BB12/BC12*20,0) -> 89.756098 | BE12: 4.1731 | BF12: 40.52
A13: 46247 | B13: =TEXT(A13,"aaa") -> Thu | C13: 59225.78 | D13: 57041.08 | E13: 1593 | F13: =IFERROR(D13/E13,0) -> 35.807332 | G13: =IFERROR(D13/C13,0) -> 0.96311235 | H13: 5312 | I13: =IFERROR(H13/E13,0) -> 3.3345888 | J13: 0.64030132 | K13: 14864.39 | L13: =IFERROR(K13/D13,0) -> 0.26059096 | M13: 573 | N13: 134 | O13: =IFERROR(N13/M13,0) -> 0.23385689 | P13: 17694.54 | Q13: =IFERROR(P13/D13,0) -> 0.31020696 | R13: 685.45 | S13: =IFERROR(R13/D13,0) -> 0.012016778 | T13: 264.17 | U13: 275.45 | V13: 28.5 | W13: 241.45 | X13: 230.1675 | Y13: =T13*V13 -> 7528.845 | Z13: =IFERROR(Y13/D13,0) -> 0.13198987 | AA13: =IFERROR(D13/T13,0) -> 215.92565 | AB13: =IFERROR(ABS(X13-W13)/W13,0) -> 0.046728101 | AC13: 155.89 | AD13: 58.35 | AE13: 86.28 | AF13: 128.93 | AG13: 414.87 | AH13: 1234 | AI13: =IFERROR(AH13/E13,0) -> 0.77463905 | AJ13: 1 | AK13: =IFERROR(1-AJ13/E13,0) -> 0.99937225 | AL13: =IFERROR(AJ13/E13*1000,0) -> 0.62774639 | AM13: 98.667 | AN13: 0 | AO13: 1933 | AP13: 54 | AQ13: =IFERROR(AP13/AO13,0) -> 0.027935851 | AR13: 93.267 | AS13: 0 | AT13: 38 | AU13: 37 | AV13: =IFERROR(AU13/AT13,0) -> 0.97368421 | AW13: 3 | AX13: =IFERROR(AW13/AU13,0) -> 0.081081081 | AY13: 34 | AZ13: =IFERROR(AY13/AT13,0) -> 0.89473684 | BA13: 0.048387097 | BB13: 168 | BC13: 37 | BD13: =IFERROR(BB13/BC13*20,0) -> 90.810811 | BE13: 4.2575 | BF13: 17.96
A14: 46248 | B14: =TEXT(A14,"aaa") -> Fri | C14: 70765.05 | D14: 68068.84 | E14: 1922 | F14: =IFERROR(D14/E14,0) -> 35.41563 | G14: =IFERROR(D14/C14,0) -> 0.96189913 | H14: 6386 | I14: =IFERROR(H14/E14,0) -> 3.3225806 | J14: 0.62278876 | K14: 17581.81 | L14: =IFERROR(K14/D14,0) -> 0.25829454 | M14: 725 | N14: 157 | O14: =IFERROR(N14/M14,0) -> 0.21655172 | P14: 21122.82 | Q14: =IFERROR(P14/D14,0) -> 0.31031556 | R14: 788.28 | S14: =IFERROR(R14/D14,0) -> 0.011580629 | T14: 300.13 | U14: 309.77 | V14: 28.5 | W14: 275.775 | X14: 266.1325 | Y14: =T14*V14 -> 8553.705 | Z14: =IFERROR(Y14/D14,0) -> 0.12566256 | AA14: =IFERROR(D14/T14,0) -> 226.79785 | AB14: =IFERROR(ABS(X14-W14)/W14,0) -> 0.034965098 | AC14: 155.69 | AD14: 57.58 | AE14: 86.94 | AF14: 130.29 | AG14: 421.83 | AH14: 1472 | AI14: =IFERROR(AH14/E14,0) -> 0.76586889 | AJ14: 5 | AK14: =IFERROR(1-AJ14/E14,0) -> 0.99739854 | AL14: =IFERROR(AJ14/E14*1000,0) -> 2.6014568 | AM14: 98.667 | AN14: 5 | AO14: 2479 | AP14: 74 | AQ14: =IFERROR(AP14/AO14,0) -> 0.029850746 | AR14: 91.667 | AS14: 0 | AT14: 44 | AU14: 44 | AV14: =IFERROR(AU14/AT14,0) -> 1 | AW14: 0 | AX14: =IFERROR(AW14/AU14,0) -> 0 | AY14: 38 | AZ14: =IFERROR(AY14/AT14,0) -> 0.86363636 | BA14: 0.048387097 | BB14: 186 | BC14: 42 | BD14: =IFERROR(BB14/BC14*20,0) -> 88.571429 | BE14: 4.0874 | BF14: 38.21
A15: 46249 | B15: =TEXT(A15,"aaa") -> Sat | C15: 75705.5 | D15: 76512.05 | E15: 2125 | F15: =IFERROR(D15/E15,0) -> 36.005671 | G15: =IFERROR(D15/C15,0) -> 1.0106538 | H15: 7122 | I15: =IFERROR(H15/E15,0) -> 3.3515294 | J15: 0.64564706 | K15: 20624.22 | L15: =IFERROR(K15/D15,0) -> 0.26955519 | M15: 753 | N15: 174 | O15: =IFERROR(N15/M15,0) -> 0.2310757 | P15: 23981.49 | Q15: =IFERROR(P15/D15,0) -> 0.31343416 | R15: 916.96 | S15: =IFERROR(R15/D15,0) -> 0.011984517 | T15: 319.66 | U15: 330.95 | V15: 28.5 | W15: 296.95 | X15: 285.6575 | Y15: =T15*V15 -> 9110.31 | Z15: =IFERROR(Y15/D15,0) -> 0.11907026 | AA15: =IFERROR(D15/T15,0) -> 239.35447 | AB15: =IFERROR(ABS(X15-W15)/W15,0) -> 0.038028288 | AC15: 158.02 | AD15: 58.32 | AE15: 88.18 | AF15: 131.69 | AG15: 434.35 | AH15: 1561 | AI15: =IFERROR(AH15/E15,0) -> 0.73458824 | AJ15: 3 | AK15: =IFERROR(1-AJ15/E15,0) -> 0.99858824 | AL15: =IFERROR(AJ15/E15*1000,0) -> 1.4117647 | AM15: 98.667 | AN15: 0 | AO15: 2685 | AP15: 76 | AQ15: =IFERROR(AP15/AO15,0) -> 0.0283054 | AR15: 91.533 | AS15: 0 | AT15: 48 | AU15: 45 | AV15: =IFERROR(AU15/AT15,0) -> 0.9375 | AW15: 4 | AX15: =IFERROR(AW15/AU15,0) -> 0.088888889 | AY15: 43 | AZ15: =IFERROR(AY15/AT15,0) -> 0.89583333 | BA15: 0.048387097 | BB15: 205 | BC15: 46 | BD15: =IFERROR(BB15/BC15*20,0) -> 89.130435 | BE15: 3.992 | BF15: 64.05
A16: 46250 | B16: =TEXT(A16,"aaa") -> Sun | C16: 71075.89 | D16: 68620.32 | E16: 1921 | F16: =IFERROR(D16/E16,0) -> 35.721145 | G16: =IFERROR(D16/C16,0) -> 0.96545144 | H16: 6402 | I16: =IFERROR(H16/E16,0) -> 3.3326393 | J16: 0.62363352 | K16: 18891.16 | L16: =IFERROR(K16/D16,0) -> 0.27529979 | M16: 723 | N16: 171 | O16: =IFERROR(N16/M16,0) -> 0.23651452 | P16: 21019.54 | Q16: =IFERROR(P16/D16,0) -> 0.30631655 | R16: 828.77 | S16: =IFERROR(R16/D16,0) -> 0.012077618 | T16: 298.75 | U16: 309.67 | V16: 28.5 | W16: 275.675 | X16: 264.7525 | Y16: =T16*V16 -> 8514.375 | Z16: =IFERROR(Y16/D16,0) -> 0.1240795 | AA16: =IFERROR(D16/T16,0) -> 229.69145 | AB16: =IFERROR(ABS(X16-W16)/W16,0) -> 0.03962093 | AC16: 159.01 | AD16: 58.19 | AE16: 86.79 | AF16: 130.02 | AG16: 424.74 | AH16: 1425 | AI16: =IFERROR(AH16/E16,0) -> 0.74180115 | AJ16: 2 | AK16: =IFERROR(1-AJ16/E16,0) -> 0.99895888 | AL16: =IFERROR(AJ16/E16*1000,0) -> 1.0411244 | AM16: 100 | AN16: 1 | AO16: 2454 | AP16: 65 | AQ16: =IFERROR(AP16/AO16,0) -> 0.026487368 | AR16: 89.667 | AS16: 0 | AT16: 44 | AU16: 44 | AV16: =IFERROR(AU16/AT16,0) -> 1 | AW16: 1 | AX16: =IFERROR(AW16/AU16,0) -> 0.022727273 | AY16: 38 | AZ16: =IFERROR(AY16/AT16,0) -> 0.86363636 | BA16: 0.048387097 | BB16: 168 | BC16: 36 | BD16: =IFERROR(BB16/BC16*20,0) -> 93.333333 | BE16: 4.0067 | BF16: 27.32
... A18: 46252 | B18: =TEXT(A18,"aaa") -> Tue | C18: 57207.16 | D18: 55987.74 | E18: 1564 | F18: =IFERROR(D18/E18,0) -> 35.797788 | G18: =IFERROR(D18/C18,0) -> 0.97868414 | H18: 5221 | I18: =IFERROR(H18/E18,0) -> 3.3382353 | J18: 0.62723785 | K18: 14893.8 | L18: =IFERROR(K18/D18,0) -> 0.26601895 | M18: 583 | N18: 143 | O18: =IFERROR(N18/M18,0) -> 0.24528302 | P18: 17479.01 | Q18: =IFERROR(P18/D18,0) -> 0.31219353 | R18: 616.51 | S18: =IFERROR(R18/D18,0) -> 0.011011518 | T18: 260.23 | U18: 272.45 | V18: 28.5 | W18: 238.45 | X18: 226.2325 | Y18: =T18*V18 -> 7416.555 | Z18: =IFERROR(Y18/D18,0) -> 0.13246748 | AA18: =IFERROR(D18/T18,0) -> 215.14714 | AB18: =IFERROR(ABS(X18-W18)/W18,0) -> 0.051237157 | AC18: 158.34 | AD18: 58.36 | AE18: 86.24 | AF18: 129.08 | AG18: 416.28 | AH18: 1198 | AI18: =IFERROR(AH18/E18,0) -> 0.76598465 | AJ18: 1 | AK18: =IFERROR(1-AJ18/E18,0) -> 0.99936061 | AL18: =IFERROR(AJ18/E18*1000,0) -> 0.63938619 | AM18: 100 | AN18: 0 | AO18: 1902 | AP18: 49 | AQ18: =IFERROR(AP18/AO18,0) -> 0.025762355 | AR18: 91.867 | AS18: 76 | AT18: 38 | AU18: 38 | AV18: =IFERROR(AU18/AT18,0) -> 1 | AW18: 4 | AX18: =IFERROR(AW18/AU18,0) -> 0.10526316 | AY18: 34 | AZ18: =IFERROR(AY18/AT18,0) -> 0.89473684 | BA18: 0.047619048 | BB18: 162 | BC18: 35 | BD18: =IFERROR(BB18/BC18*20,0) -> 92.571429 | BE18: 4.1375 | BF18: 8.5
A20: 浅蓝 = 每天填的原子数（来自 POS / KDS / 得来速计时 / 排班考勤 / 废弃登记 / 食安检查 / 顾客调研）。白色 = 公式，勿改。条件格式里的红线为示例硬编码值，与「目标与口径」保持一致时才准确——改了阈值请同步这里的条件格式，或直接看「店长看板」的状态列（那里是回查公式，永远准）。

Sheet 优先级矩阵
A1: 优先级矩阵 · Priority Matrix（影响度 × 可控度）
A2: 行动分 = 超线带宽 × 影响度 × 可控度 ×（红灯 2 倍）。全部是公式：改「目标与口径」的阈值或影响度/可控度，这里的分数和象限会一起变。
A4: 指标ID | B4: 指标 | C4: 最新值 | D4: 目标 | E4: 状态 | F4: 影响度 | G4: 可控度 | H4: 象限 | I4: 责任人 | J4: 行动分 | K4: 行动卡 | L4: 第一动作 | M4: 排名
A5: delivery_rating | B5: 外卖平台评分 | C5: =IFERROR(INDEX(每日经营日报!$BE$5:$BE$18,MATCH(店长看板!$B$3,每日经营日报!$A$5:$A$18,0)),0) -> 4.1375 | D5: =INDEX(目标与口径!$F$5:$F$36,MATCH("delivery_rating",目标与口径!$A$5:$A$36,0)) -> 4.8 | E5: =IFERROR(IF(INDEX(目标与口径!$E$5:$E$36,MATCH("delivery_rating",目标与口径!$A$5:$A$36,0))="越高越好",IF($C$5>=INDEX(目标与口径!$G$5:$G$36,MATCH("delivery_rating",目标与口径!$A$5:$A$36,0)),"绿",IF($C$5>=INDEX(目标与口径!$H$5:$H$36,MATCH("delivery_rating",目标与口径!$A$5:$A$36,0)),"黄","红")),IF($C$5<=INDEX(目标与口径!$G$5:$G$36,MATCH("delivery_rating",目标与口径!$A$5:$A$36,0)),"绿",IF($C$5<=INDEX(目标与口径!$H$5:$H$36,MATCH("delivery_rating",目标与口径!$A$5:$A$36,0)),"黄","红"))),"—") -> 红 | F5: =INDEX(目标与口径!$L$5:$L$36,MATCH("delivery_rating",目标与口径!$A$5:$A$36,0)) -> 0.7 | G5: =INDEX(目标与口径!$M$5:$M$36,MATCH("delivery_rating",目标与口径!$A$5:$A$36,0)) -> 0.55 | H5: =IF($F$5>=0.7,IF($G$5>=0.7,"Q1 今天就做","Q2 上报求援"),IF($G$5>=0.7,"Q3 顺手做掉","Q4 记录观察")) -> Q2 上报求援 | I5: =INDEX(目标与口径!$J$5:$J$36,MATCH("delivery_rating",目标与口径!$A$5:$A$36,0)) -> 店长 | J5: =IFERROR(ROUND(IFERROR(MAX(0,IF(INDEX(目标与口径!$E$5:$E$36,MATCH("delivery_rating",目标与口径!$A$5:$A$36,0))="越高越好",INDEX(目标与口径!$G$5:$G$36,MATCH("delivery_rating",目标与口径!$A$5:$A$36,0))-$C$5,$C$5-INDEX(目标与口径!$G$5:$G$36,MATCH("delivery_rating",目标与口径!$A$5:$A$36,0)))/ABS(INDEX(目标与口径!$H$5:$H$36,MATCH("delivery_rating",目标与口径!$A$5:$A$36,0))-INDEX(目标与口径!$G$5:$G$36,MATCH("delivery_rating",目标与口径!$A$5:$A$36,0)))),0)*$F$5*$G$5*IF($E$5="红",2,1),2),0) -> 2.17 | K5: =INDEX(目标与口径!$N$5:$N$36,MATCH("delivery_rating",目标与口径!$A$5:$A$36,0)) -> PB-03 | L5: 全时段慢=打包流程问题（上报）；只高峰慢=给外送单独留打包位 | M5: =RANK($J$5,$J$5:$J$36,0) -> 1
A6: speed_hit_rate | B6: 服务速度达标率 | C6: =IFERROR(INDEX(每日经营日报!$AI$5:$AI$18,MATCH(店长看板!$B$3,每日经营日报!$A$5:$A$18,0)),0) -> 0.76598465 | D6: =INDEX(目标与口径!$F$5:$F$36,MATCH("speed_hit_rate",目标与口径!$A$5:$A$36,0)) -> 0.9 | E6: =IFERROR(IF(INDEX(目标与口径!$E$5:$E$36,MATCH("speed_hit_rate",目标与口径!$A$5:$A$36,0))="越高越好",IF($C$6>=INDEX(目标与口径!$G$5:$G$36,MATCH("speed_hit_rate",目标与口径!$A$5:$A$36,0)),"绿",IF($C$6>=INDEX(目标与口径!$H$5:$H$36,MATCH("speed_hit_rate",目标与口径!$A$5:$A$36,0)),"黄","红")),IF($C$6<=INDEX(目标与口径!$G$5:$G$36,MATCH("speed_hit_rate",目标与口径!$A$5:$A$36,0)),"绿",IF($C$6<=INDEX(目标与口径!$H$5:$H$36,MATCH("speed_hit_rate",目标与口径!$A$5:$A$36,0)),"黄","红"))),"—") -> 红 | F6: =INDEX(目标与口径!$L$5:$L$36,MATCH("speed_hit_rate",目标与口径!$A$5:$A$36,0)) -> 0.85 | G6: =INDEX(目标与口径!$M$5:$M$36,MATCH("speed_hit_rate",目标与口径!$A$5:$A$36,0)) -> 0.85 | H6: =IF($F$6>=0.7,IF($G$6>=0.7,"Q1 今天就做","Q2 上报求援"),IF($G$6>=0.7,"Q3 顺手做掉","Q4 记录观察")) -> Q1 今天就做 | I6: =INDEX(目标与口径!$J$5:$J$36,MATCH("speed_hit_rate",目标与口径!$A$5:$A$36,0)) -> 值班经理 | J6: =IFERROR(ROUND(IFERROR(MAX(0,IF(INDEX(目标与口径!$E$5:$E$36,MATCH("speed_hit_rate",目标与口径!$A$5:$A$36,0))="越高越好",INDEX(目标与口径!$G$5:$G$36,MATCH("speed_hit_rate",目标与口径!$A$5:$A$36,0))-$C$6,$C$6-INDEX(目标与口径!$G$5:$G$36,MATCH("speed_hit_rate",目标与口径!$A$5:$A$36,0)))/ABS(INDEX(目标与口径!$H$5:$H$36,MATCH("speed_hit_rate",目标与口径!$A$5:$A$36,0))-INDEX(目标与口径!$G$5:$G$36,MATCH("speed_hit_rate",目标与口径!$A$5:$A$36,0)))),0)*$F$6*$G$6*IF($E$6="红",2,1),2),0) -> 2.06 | K6: =INDEX(目标与口径!$N$5:$N$36,MATCH("speed_hit_rate",目标与口径!$A$5:$A$36,0)) -> PB-04 | L6: 先分段定位（点单/排队/取餐窗/制作），再看是结构问题还是产能问题 | M6: =RANK($J$6,$J$5:$J$36,0) -> 2
A7: late_rate | B7: 迟到率 | C7: =IFERROR(INDEX(每日经营日报!$AX$5:$AX$18,MATCH(店长看板!$B$3,每日经营日报!$A$5:$A$18,0)),0) -> 0.10526316 | D7: =INDEX(目标与口径!$F$5:$F$36,MATCH("late_rate",目标与口径!$A$5:$A$36,0)) -> 0.02 | E7: =IFERROR(IF(INDEX(目标与口径!$E$5:$E$36,MATCH("late_rate",目标与口径!$A$5:$A$36,0))="越高越好",IF($C$7>=INDEX(目标与口径!$G$5:$G$36,MATCH("late_rate",目标与口径!$A$5:$A$36,0)),"绿",IF($C$7>=INDEX(目标与口径!$H$5:$H$36,MATCH("late_rate",目标与口径!$A$5:$A$36,0)),"黄","红")),IF($C$7<=INDEX(目标与口径!$G$5:$G$36,MATCH("late_rate",目标与口径!$A$5:$A$36,0)),"绿",IF($C$7<=INDEX(目标与口径!$H$5:$H$36,MATCH("late_rate",目标与口径!$A$5:$A$36,0)),"黄","红"))),"—") -> 红 | F7: =INDEX(目标与口径!$L$5:$L$36,MATCH("late_rate",目标与口径!$A$5:$A$36,0)) -> 0.4 | G7: =INDEX(目标与口径!$M$5:$M$36,MATCH("late_rate",目标与口径!$A$5:$A$36,0)) -> 0.85 | H7: =IF($F$7>=0.7,IF($G$7>=0.7,"Q1 今天就做","Q2 上报求援"),IF($G$7>=0.7,"Q3 顺手做掉","Q4 记录观察")) -> Q3 顺手做掉 | I7: =INDEX(目标与口径!$J$5:$J$36,MATCH("late_rate",目标与口径!$A$5:$A$36,0)) -> 组长 | J7: =IFERROR(ROUND(IFERROR(MAX(0,IF(INDEX(目标与口径!$E$5:$E$36,MATCH("late_rate",目标与口径!$A$5:$A$36,0))="越高越好",INDEX(目标与口径!$G$5:$G$36,MATCH("late_rate",目标与口径!$A$5:$A$36,0))-$C$7,$C$7-INDEX(目标与口径!$G$5:$G$36,MATCH("late_rate",目标与口径!$A$5:$A$36,0)))/ABS(INDEX(目标与口径!$H$5:$H$36,MATCH("late_rate",目标与口径!$A$5:$A$36,0))-INDEX(目标与口径!$G$5:$G$36,MATCH("late_rate",目标与口径!$A$5:$A$36,0)))),0)*$F$7*$G$7*IF($E$7="红",2,1),2),0) -> 1.02 | K7: =INDEX(目标与口径!$N$5:$N$36,MATCH("late_rate",目标与口径!$A$5:$A$36,0)) -> PB-07 | L7: 看 SPLH 与速度的组合：都差 = 排班结构错，调岗位不是加人头 | M7: =RANK($J$7,$J$5:$J$36,0) -> 3
A8: equipment_downtime | B8: 设备停机时长 | C8: =IFERROR(INDEX(每日经营日报!$AS$5:$AS$18,MATCH(店长看板!$B$3,每日经营日报!$A$5:$A$18,0)),0) -> 76 | D8: =INDEX(目标与口径!$F$5:$F$36,MATCH("equipment_downtime",目标与口径!$A$5:$A$36,0)) -> 0 | E8: =IFERROR(IF(INDEX(目标与口径!$E$5:$E$36,MATCH("equipment_downtime",目标与口径!$A$5:$A$36,0))="越高越好",IF($C$8>=INDEX(目标与口径!$G$5:$G$36,MATCH("equipment_downtime",目标与口径!$A$5:$A$36,0)),"绿",IF($C$8>=INDEX(目标与口径!$H$5:$H$36,MATCH("equipment_downtime",目标与口径!$A$5:$A$36,0)),"黄","红")),IF($C$8<=INDEX(目标与口径!$G$5:$G$36,MATCH("equipment_downtime",目标与口径!$A$5:$A$36,0)),"绿",IF($C$8<=INDEX(目标与口径!$H$5:$H$36,MATCH("equipment_downtime",目标与口径!$A$5:$A$36,0)),"黄","红"))),"—") -> 红 | F8: =INDEX(目标与口径!$L$5:$L$36,MATCH("equipment_downtime",目标与口径!$A$5:$A$36,0)) -> 0.7 | G8: =INDEX(目标与口径!$M$5:$M$36,MATCH("equipment_downtime",目标与口径!$A$5:$A$36,0)) -> 0.5 | H8: =IF($F$8>=0.7,IF($G$8>=0.7,"Q1 今天就做","Q2 上报求援"),IF($G$8>=0.7,"Q3 顺手做掉","Q4 记录观察")) -> Q2 上报求援 | I8: =INDEX(目标与口径!$J$5:$J$36,MATCH("equipment_downtime",目标与口径!$A$5:$A$36,0)) -> 店长 | J8: =IFERROR(ROUND(IFERROR(MAX(0,IF(INDEX(目标与口径!$E$5:$E$36,MATCH("equipment_downtime",目标与口径!$A$5:$A$36,0))="越高越好",INDEX(目标与口径!$G$5:$G$36,MATCH("equipment_downtime",目标与口径!$A$5:$A$36,0))-$C$8,$C$8-INDEX(目标与口径!$G$5:$G$36,MATCH("equipment_downtime",目标与口径!$A$5:$A$36,0)))/ABS(INDEX(目标与口径!$H$5:$H$36,MATCH("equipment_downtime",目标与口径!$A$5:$A$36,0))-INDEX(目标与口径!$G$5:$G$36,MATCH("equipment_downtime",目标与口径!$A$5:$A$36,0)))),0)*$F$8*$G$8*IF($E$8="红",2,1),2),0) -> 0.95 | K8: =INDEX(目标与口径!$N$5:$N$36,MATCH("equipment_downtime",目标与口径!$A$5:$A$36,0)) -> PB-11 | L8: 先决定是否停售并同步到所有点单渠道（含外送平台），再报修 | M8: =RANK($J$8,$J$5:$J$36,0) -> 4
A9: labor_schedule_variance | B9: 工时排班偏差 | C9: =IFERROR(INDEX(每日经营日报!$AB$5:$AB$18,MATCH(店长看板!$B$3,每日经营日报!$A$5:$A$18,0)),0) -> 0.051237157 | D9: =INDEX(目标与口径!$F$5:$F$36,MATCH("labor_schedule_variance",目标与口径!$A$5:$A$36,0)) -> 0.02 | E9: =IFERROR(IF(INDEX(目标与口径!$E$5:$E$36,MATCH("labor_schedule_variance",目标与口径!$A$5:$A$36,0))="越高越好",IF($C$9>=INDEX(目标与口径!$G$5:$G$36,MATCH("labor_schedule_variance",目标与口径!$A$5:$A$36,0)),"绿",IF($C$9>=INDEX(目标与口径!$H$5:$H$36,MATCH("labor_schedule_variance",目标与口径!$A$5:$A$36,0)),"黄","红")),IF($C$9<=INDEX(目标与口径!$G$5:$G$36,MATCH("labor_schedule_variance",目标与口径!$A$5:$A$36,0)),"绿",IF($C$9<=INDEX(目标与口径!$H$5:$H$36,MATCH("labor_schedule_variance",目标与口径!$A$5:$A$36,0)),"黄","红"))),"—") -> 黄 | F9: =INDEX(目标与口径!$L$5:$L$36,MATCH("labor_schedule_variance",目标与口径!$A$5:$A$36,0)) -> 0.6 | G9: =INDEX(目标与口径!$M$5:$M$36,MATCH("labor_schedule_variance",目标与口径!$A$5:$A$36,0)) -> 0.95 | H9: =IF($F$9>=0.7,IF($G$9>=0.7,"Q1 今天就做","Q2 上报求援"),IF($G$9>=0.7,"Q3 顺手做掉","Q4 记录观察")) -> Q3 顺手做掉 | I9: =INDEX(目标与口径!$J$5:$J$36,MATCH("labor_schedule_variance",目标与口径!$A$5:$A$36,0)) -> 值班经理 | J9: =IFERROR(ROUND(IFERROR(MAX(0,IF(INDEX(目标与口径!$E$5:$E$36,MATCH("labor_schedule_variance",目标与口径!$A$5:$A$36,0))="越高越好",INDEX(目标与口径!$G$5:$G$36,MATCH("labor_schedule_variance",目标与口径!$A$5:$A$36,0))-$C$9,$C$9-INDEX(目标与口径!$G$5:$G$36,MATCH("labor_schedule_variance",目标与口径!$A$5:$A$36,0)))/ABS(INDEX(目标与口径!$H$5:$H$36,MATCH("labor_schedule_variance",目标与口径!$A$5:$A$36,0))-INDEX(目标与口径!$G$5:$G$36,MATCH("labor_schedule_variance",目标与口径!$A$5:$A$36,0)))),0)*$F$9*$G$9*IF($E$9="红",2,1),2),0) -> 0.4 | K9: =INDEX(目标与口径!$N$5:$N$36,MATCH("labor_schedule_variance",目标与口径!$A$5:$A$36,0)) -> PB-07 | L9: 看 SPLH 与速度的组合：都差 = 排班结构错，调岗位不是加人头 | M9: =RANK($J$9,$J$5:$J$36,0) -> 5
A10: upsell_rate | B10: 附加销售率 | C10: =IFERROR(INDEX(每日经营日报!$O$5:$O$18,MATCH(店长看板!$B$3,每日经营日报!$A$5:$A$18,0)),0) -> 0.24528302 | D10: =INDEX(目标与口径!$F$5:$F$36,MATCH("upsell_rate",目标与口径!$A$5:$A$36,0)) -> 0.3 | E10: =IFERROR(IF(INDEX(目标与口径!$E$5:$E$36,MATCH("upsell_rate",目标与口径!$A$5:$A$36,0))="越高越好",IF($C$10>=INDEX(目标与口径!$G$5:$G$36,MATCH("upsell_rate",目标与口径!$A$5:$A$36,0)),"绿",IF($C$10>=INDEX(目标与口径!$H$5:$H$36,MATCH("upsell_rate",目标与口径!$A$5:$A$36,0)),"黄","红")),IF($C$10<=INDEX(目标与口径!$G$5:$G$36,MATCH("upsell_rate",目标与口径!$A$5:$A$36,0)),"绿",IF($C$10<=INDEX(目标与口径!$H$5:$H$36,MATCH("upsell_rate",目标与口径!$A$5:$A$36,0)),"黄","红"))),"—") -> 黄 | F10: =INDEX(目标与口径!$L$5:$L$36,MATCH("upsell_rate",目标与口径!$A$5:$A$36,0)) -> 0.55 | G10: =INDEX(目标与口径!$M$5:$M$36,MATCH("upsell_rate",目标与口径!$A$5:$A$36,0)) -> 0.9 | H10: =IF($F$10>=0.7,IF($G$10>=0.7,"Q1 今天就做","Q2 上报求援"),IF($G$10>=0.7,"Q3 顺手做掉","Q4 记录观察")) -> Q3 顺手做掉 | I10: =INDEX(目标与口径!$J$5:$J$36,MATCH("upsell_rate",目标与口径!$A$5:$A$36,0)) -> 组长 | J10: =IFERROR(ROUND(IFERROR(MAX(0,IF(INDEX(目标与口径!$E$5:$E$36,MATCH("upsell_rate",目标与口径!$A$5:$A$36,0))="越高越好",INDEX(目标与口径!$G$5:$G$36,MATCH("upsell_rate",目标与口径!$A$5:$A$36,0))-$C$10,$C$10-INDEX(目标与口径!$G$5:$G$36,MATCH("upsell_rate",目标与口径!$A$5:$A$36,0)))/ABS(INDEX(目标与口径!$H$5:$H$36,MATCH("upsell_rate",目标与口径!$A$5:$A$36,0))-INDEX(目标与口径!$G$5:$G$36,MATCH("upsell_rate",目标与口径!$A$5:$A$36,0)))),0)*$F$10*$G$10*IF($E$10="红",2,1),2),0) -> 0.29 | K10: =INDEX(目标与口径!$N$5:$N$36,MATCH("upsell_rate",目标与口径!$A$5:$A$36,0)) -> PB-02 | L10: 拉附加销售率 × 收银员，训练员跟班 2 小时；只主推 1 个品 | M10: =RANK($J$10,$J$5:$J$36,0) -> 6
A11: holding_time_violation | B11: 保温超时率 | C11: =IFERROR(INDEX(每日经营日报!$AQ$5:$AQ$18,MATCH(店长看板!$B$3,每日经营日报!$A$5:$A$18,0)),0) -> 0.025762355 | D11: =INDEX(目标与口径!$F$5:$F$36,MATCH("holding_time_violation",目标与口径!$A$5:$A$36,0)) -> 0.01 | E11: =IFERROR(IF(INDEX(目标与口径!$E$5:$E$36,MATCH("holding_time_violation",目标与口径!$A$5:$A$36,0))="越高越好",IF($C$11>=INDEX(目标与口径!$G$5:$G$36,MATCH("holding_time_violation",目标与口径!$A$5:$A$36,0)),"绿",IF($C$11>=INDEX(目标与口径!$H$5:$H$36,MATCH("holding_time_violation",目标与口径!$A$5:$A$36,0)),"黄","红")),IF($C$11<=INDEX(目标与口径!$G$5:$G$36,MATCH("holding_time_violation",目标与口径!$A$5:$A$36,0)),"绿",IF($C$11<=INDEX(目标与口径!$H$5:$H$36,MATCH("holding_time_violation",目标与口径!$A$5:$A$36,0)),"黄","红"))),"—") -> 黄 | F11: =INDEX(目标与口径!$L$5:$L$36,MATCH("holding_time_violation",目标与口径!$A$5:$A$36,0)) -> 0.7 | G11: =INDEX(目标与口径!$M$5:$M$36,MATCH("holding_time_violation",目标与口径!$A$5:$A$36,0)) -> 0.9 | H11: =IF($F$11>=0.7,IF($G$11>=0.7,"Q1 今天就做","Q2 上报求援"),IF($G$11>=0.7,"Q3 顺手做掉","Q4 记录观察")) -> Q1 今天就做 | I11: =INDEX(目标与口径!$J$5:$J$36,MATCH("holding_time_violation",目标与口径!$A$5:$A$36,0)) -> 组长 | J11: =IFERROR(ROUND(IFERROR(MAX(0,IF(INDEX(目标与口径!$E$5:$E$36,MATCH("holding_time_violation",目标与口径!$A$5:$A$36,0))="越高越好",INDEX(目标与口径!$G$5:$G$36,MATCH("holding_time_violation",目标与口径!$A$5:$A$36,0))-$C$11,$C$11-INDEX(目标与口径!$G$5:$G$36,MATCH("holding_time_violation",目标与口径!$A$5:$A$36,0)))/ABS(INDEX(目标与口径!$H$5:$H$36,MATCH("holding_time_violation",目标与口径!$A$5:$A$36,0))-INDEX(目标与口径!$G$5:$G$36,MATCH("holding_time_violation",目标与口径!$A$5:$A$36,0)))),0)*$F$11*$G$11*IF($E$11="红",2,1),2),0) -> 0.18 | K11: =INDEX(目标与口径!$N$5:$N$36,MATCH("holding_time_violation",目标与口径!$A$5:$A$36,0)) -> PB-06 | L11: 分成品/原料/保温三类：成品高改批量，原料高查先进先出 | M11: =RANK($J$11,$J$5:$J$36,0) -> 7
A12: net_sales | B12: 净销售额 | C12: =IFERROR(INDEX(每日经营日报!$D$5:$D$18,MATCH(店长看板!$B$3,每日经营日报!$A$5:$A$18,0)),0) -> 55987.74 | D12: =INDEX(目标与口径!$F$5:$F$36,MATCH("net_sales",目标与口径!$A$5:$A$36,0)) -> 62000 | E12: =IFERROR(IF(INDEX(目标与口径!$E$5:$E$36,MATCH("net_sales",目标与口径!$A$5:$A$36,0))="越高越好",IF($C$12>=INDEX(目标与口径!$G$5:$G$36,MATCH("net_sales",目标与口径!$A$5:$A$36,0)),"绿",IF($C$12>=INDEX(目标与口径!$H$5:$H$36,MATCH("net_sales",目标与口径!$A$5:$A$36,0)),"黄","红")),IF($C$12<=INDEX(目标与口径!$G$5:$G$36,MATCH("net_sales",目标与口径!$A$5:$A$36,0)),"绿",IF($C$12<=INDEX(目标与口径!$H$5:$H$36,MATCH("net_sales",目标与口径!$A$5:$A$36,0)),"黄","红"))),"—") -> 黄 | F12: =INDEX(目标与口径!$L$5:$L$36,MATCH("net_sales",目标与口径!$A$5:$A$36,0)) -> 1 | G12: =INDEX(目标与口径!$M$5:$M$36,MATCH("net_sales",目标与口径!$A$5:$A$36,0)) -> 0.45 | H12: =IF($F$12>=0.7,IF($G$12>=0.7,"Q1 今天就做","Q2 上报求援"),IF($G$12>=0.7,"Q3 顺手做掉","Q4 记录观察")) -> Q2 上报求援 | I12: =INDEX(目标与口径!$J$5:$J$36,MATCH("net_sales",目标与口径!$A$5:$A$36,0)) -> 店长 | J12: =IFERROR(ROUND(IFERROR(MAX(0,IF(INDEX(目标与口径!$E$5:$E$36,MATCH("net_sales",目标与口径!$A$5:$A$36,0))="越高越好",INDEX(目标与口径!$G$5:$G$36,MATCH("net_sales",目标与口径!$A$5:$A$36,0))-$C$12,$C$12-INDEX(目标与口径!$G$5:$G$36,MATCH("net_sales",目标与口径!$A$5:$A$36,0)))/ABS(INDEX(目标与口径!$H$5:$H$36,MATCH("net_sales",目标与口径!$A$5:$A$36,0))-INDEX(目标与口径!$G$5:$G$36,MATCH("net_sales",目标与口径!$A$5:$A$36,0)))),0)*$F$12*$G$12*IF($E$12="红",2,1),2),0) -> 0.15 | K12: =INDEX(目标与口径!$N$5:$N$36,MATCH("net_sales",目标与口径!$A$5:$A$36,0)) -> PB-01 | L12: 分清是客流少还是客单少：GC 跌查外部与曝光，客单跌走附加销售 | M12: =RANK($J$12,$J$5:$J$36,0) -> 8
